Workbook
Name SlicerCache_Table_9_Col_2: #N/A

Sheet SAP
A1: CLIENTE | B1: PEDIDO (14) | C1: POSICIÓN | D1: MATERIAL | E1: PROYECTO | F1: CANTIDAD | G1: TOTAL | H1: FECHA PEDIDO | I1: FECHA REQUERIDO | J1: PEDIDO CLIENTE | K1: PO_ID
A2: BUFKOR INC- | B2: 1402048632 | C2: 10 | D2: 10334816 | E2: BOLSA ROGERS ENTERPRISES 10"X4"X7-75" | F2: 17500 | G2: 18620 | H2: 45771 | I2: 45838 | K2: =CONCAT(B2,C2) -> 140204863210
A3: BUFKOR INC- | B3: 1402048797 | C3: 10 | D3: 10335265 | E3: BOLSA MAUI DIVERS 8"x5"x8" | F3: 1280 | G3: 1730.56 | H3: 45806 | I3: 45849 | K3: =CONCAT(B3,C3) -> 140204879710
A4: CHIPPENHOOK | B4: 1402048824 | C4: 10 | D4: 10332711 | E4: BOLSA FRED MEYER 4-5"x3"x5-5" | F4: 16704 | G4: 5178.24 | H4: 45814 | I4: 45877 | K4: =CONCAT(B4,C4) -> 140204882410
A5: CHIPPENHOOK | B5: 1402048833 | C5: 10 | D5: 10332711 | E5: BOLSA FRED MEYER 4-5"x3"x5-5" | F5: 54180 | G5: 27509.4 | H5: 45814 | I5: 45982 | K5: =CONCAT(B5,C5) -> 140204883310
A6: CHIPPENHOOK | B6: 1402048833 | C6: 20 | D6: 10332712 | E6: BOLSA FRED MEYER 10"x4"x8" | F6: 6240 | G6: 3931.2 | H6: 45814 | I6: 45982 | K6: =CONCAT(B6,C6) -> 140204883320
A7: BUFKOR INC- | B7: 1402049194 | C7: 10 | D7: 10330512 | E7: Bolsa Almagen Corp 8"x4"x10" | F7: 2000 | G7: 5856 | H7: 45923 | I7: 45931 | K7: =CONCAT(B7,C7) -> 140204919410
A8: BUFKOR INC- | B8: 1402049207 | C8: 10 | D8: 10271087 | E8: Bolsa Finks Jewelers 6-5"x3-5"x6-5" | F8: 9000 | G8: 5040 | H8: 45923 | I8: 45894 | K8: =CONCAT(B8,C8) -> 140204920710
A9: BUFKOR INC- | B9: 1402049437 | C9: 10 | D9: 10276560 | E9: Bolsa Finks Jwls 10x5x10" | F9: 3000 | G9: 3528 | H9: 45940 | I9: 45999 | K9: =CONCAT(B9,C9) -> 140204943710
A10: BUFKOR INC- | B10: 1402049207 | C10: 20 | D10: 10271097 | E10: Bolsa Finks Jewelers 7"x5"x9" | F10: 12000 | G10: 8736 | H10: 45923 | I10: 45894 | K10: =CONCAT(B10,C10) -> 140204920720
A11: BUFKOR INC- | B11: 1402049238 | C11: 10 | D11: 10335266 | E11: BOLSA MAUI DIVERS 10"x6"x10" | F11: 3040 | G11: 5496.32 | H11: 45918 | I11: 45960 | K11: =CONCAT(B11,C11) -> 140204923810
A12: BUFKOR INC- | B12: 1402049263 | C12: 10 | D12: 10269533 | E12: FOLDER GOLD CASTER LAWRENCE | F12: 3000 | G12: 2415 | H12: 45918 | I12: 45961 | K12: =CONCAT(B12,C12) -> 140204926310
A13: BUFKOR INC- | B13: 1402049277 | C13: 10 | D13: 10341337 | E13: BOLSA ELEGANCE 8x4x10 IN FL | F13: 5000 | G13: 5480 | H13: 45918 | I13: 45940 | K13: =CONCAT(B13,C13) -> 140204927710
... A59: UNIPACK, S-A- DE C-V- | B59: 1402049321 | C59: 10 | D59: 10275715 | E59: Bolsa Brillanti 6-5"x3-5"x6-5" | F59: 2500 | G59: 1925 | H59: 45965 | I59: 45972 | K59: =CONCAT(B59,C59) -> 140204932110
A60: BUFKOR INC- | B60: 1402049543 | C60: 10 | D60: 10293780 | E60: Bolsa J-C- Jewelers 10"x4"x8" -Blue | F60: 1500 | G60: 4935 | H60: 45971 | I60: 46031 | J60: HT 811106 | K60: =CONCAT(B60,C60) -> 140204954310
A61: HOLISTIC SKIN GUATEMALA | B61: 1402048469 | C61: 20 | D61: 10338264 | E61: SKINCARE OIL - HIGH END BOX | F61: 2500 | G61: 21425 | H61: 45723 | I61: 46022 | J61: HT 810915 | K61: =CONCAT(B61,C61) -> 140204846920
A62: BUFKOR INC- | B62: 1402049268 | C62: 10 | D62: 10334969 | E62: ESTUCHE FLEMING 4 CHOCOLATES 2024 | F62: 35700 | G62: 22134 | H62: 45905 | I62: 45905 | J62: 1301044455 | K62: =CONCAT(B62,C62) -> 140204926810
A63: BUFKOR INC- | B63: 1402049269 | C63: 10 | D63: 10334969 | E63: ESTUCHE FLEMING 4 CHOCOLATES 2024 | F63: 35700 | G63: 22134 | H63: 45905 | I63: 45905 | J63: 1301044445 | K63: =CONCAT(B63,C63) -> 140204926910
A64: PATRON SPIRITS MEXICO S-A DE C-V | B64: 1402049378 | C64: 20 | D64: 10333392 | E64: 8151050296_IB 1X70 EL ALTO GEX 700ml | F64: 772 | G64: 11024.16 | H64: 45925 | I64: 45982 | J64: PO 4510825712 | K64: =CONCAT(B64,C64) -> 140204937820
A65: PATRON SPIRITS MEXICO S-A DE C-V | B65: 1402049440 | C65: 10 | D65: 10334743 | E65: 8151043729_IB 1X75 EL ALTO USA 750ml | F65: 10100 | G65: 144228 | H65: 45943 | I65: 46021 | J65: PO 4510829937 | K65: =CONCAT(B65,C65) -> 140204944010
A66: UNIPACK, S-A- DE C-V- | B66: 1402049443 | C66: 10 | D66: 10308826 | E66: Estuche The Coffee Cup | F66: 1000 | G66: 4620 | H66: 45943 | I66: 45992 | J66: 4101000774 | K66: =CONCAT(B66,C66) -> 140204944310
A67: ANEJOS DE ALTURA, S-A- | B67: 1402049459 | C67: 10 | D67: 10341894 | E67: 16007447 IBC RZC XO 750ML USA RED B/B | F67: 6000 | G67: 55200 | H67: 45946 | I67: 45996 | J67: OC 4100470443 | K67: =CONCAT(B67,C67) -> 140204945910
A68: ANEJOS DE ALTURA, S-A- | B68: 1402049512 | C68: 10 | D68: 10341894 | E68: 16007447 IBC RZC XO 750ML USA RED B/B | F68: 6000 | G68: 55200 | H68: 45959 | I68: 45959 | J68: PO 4100471059 | K68: =CONCAT(B68,C68) -> 140204951210
A69: UNIPACK, S-A- DE C-V- | B69: 1402049569 | C69: 10 | D69: 10342542 | E69: ESTUCHE RON DE AUTOR | F69: 7500 | G69: 29700 | H69: 45978 | I69: 45999 | J69: 41 | K69: =CONCAT(B69,C69) -> 140204956910
A70: ANEJOS DE ALTURA, S.A. | B70: 1402049552 | C70: 10 | D70: 10318295 | E70: 16006285 CANISTER RZC EN 750ML USA 2021 | F70: 5904 | G70: 15645.6 | H70: 45974 | I70: 46001 | J70: PO 4100472321 | K70: =CONCAT(B70,C70) -> 140204955210
A71: JOYERIA GARZON, S.A. | B71: 1402049559 | C71: 10 | D71: 10331823 | E71: Bolsa Joyeria Garzon 4.75"X3.5"X6" | F71: 2000 | G71: 1600 | H71: 45975 | I71: 46036 | J71: Bolsas Joyería Garzón - Alicia | K71: =CONCAT(B71,C71) -> 140204955910
A72: BUFKOR INC. | B72: 1402049562 | C72: 10 | D72: 10321977 | E72: BOLSA NAIFEH JEWELRY 8"X4"X10" | F72: 2000 | G72: 2016 | H72: 45975 | I72: 46010 | J72: 1301044093-Doc | K72: =CONCAT(B72,C72) -> 140204956210
A73: BUFKOR INC. | B73: 1402049563 | C73: 10 | D73: 10282640 | E73: Bls Jewelry Design Center 6.5"x3.5"x6.5" | F73: 3000 | G73: 2208 | H73: 45975 | I73: 46010 | J73: 1301044927-DOC | K73: =CONCAT(B73,C73) -> 140204956310
A74: BUFKOR INC. | B74: 1402049563 | C74: 20 | D74: 10282657 | E74: Bls Jewelry Design Center 12"x5"x9" | F74: 1500 | G74: 2772 | H74: 45975 | I74: 46010 | J74: 1301044927-DOC | K74: =CONCAT(B74,C74) -> 140204956320
A75: Sileo Timeless Jewelry SAS | B75: 1402049568 | C75: 10 | D75: 10342401 | E75: BOLSA SILEO 10X4X8 IN | F75: 2000 | G75: 3960 | H75: 45978 | I75: 46038 | J75: HT 811101 | K75: =CONCAT(B75,C75) -> 140204956810
A76: SIGMAQ MEXICO S.A DE C.V | B76: 1402049570 | C76: 10 | D76: 10342419 | E76: BARBARA MADERO 160X100X140 MM | F76: 1500 | G76: 2625 | H76: 45978 | I76: 46038 | J76: HT 811078 | K76: =CONCAT(B76,C76) -> 140204957010
A77: UNIPACK, S.A. DE C.V. | B77: 1402049582 | C77: 10 | D77: 10333118 | E77: Bolsa Casa de Oro 4.5"x2.375"x5.75" Est | F77: 1500 | G77: 1065 | H77: 45980 | I77: 46038 | J77: Bolsas CDO - Alicia | K77: =CONCAT(B77,C77) -> 140204958210
A78: UNIPACK, S.A. DE C.V. | B78: 1402049582 | C78: 20 | D78: 10333119 | E78: Bolsa Casa de Oro 7"x4"x8" Est | F78: 1500 | G78: 1260 | H78: 45980 | I78: 46038 | J78: Bolsas CDO - Alicia | K78: =CONCAT(B78,C78) -> 140204958220
A79: DISTRIBUIDORA CORRIPIO, S.A.S. | B79: 1402049590 | C79: 10 | D79: 10342561 | E79: BOLSA PIRULETA 20 X 6 X16 IN FL | F79: 2000 | G79: 6940 | H79: 45981 | I79: 46035 | J79: Bolsas Distribuidora Corripio | K79: =CONCAT(B79,C79) -> 140204959010
A80: DISTRIBUIDORA CORRIPIO, S.A.S. | B80: 1402049590 | C80: 20 | D80: 10342560 | E80: BOLSA PIRULETA 16 X 5 X 14 IN FL | F80: 5000 | G80: 11600 | H80: 45981 | I80: 46035 | J80: Bolsas Distribuidora Corripio | K80: =CONCAT(B80,C80) -> 140204959020
A81: DISTRIBUIDORA CORRIPIO, S.A.S. | B81: 1402049590 | C81: 30 | D81: 10342555 | E81: BOLSA PIRULETA 13x5x10IN FL | F81: 7000 | G81: 10920 | H81: 45981 | I81: 46035 | J81: Bolsas Distribuidora Corripio | K81: =CONCAT(B81,C81) -> 140204959030

Sheet MASTER PLAN
A1: DIVISION | B1: CUSTOMER | C1: DESTINATION | D1: RSM | E1: PM | F1: PRODUCT | G1: PO | H1: POSITION | I1: MATERIAL | J1: PROJECT | K1: QTY | L1: TOTAL | M1: $/UND | N1: % OVER | O1: QTY + OVER | P1: ORDEN | Q1: ORDER DATE | R1: PO DATE | S1: REQ DATE | T1: SOLPED | U1: INITIAL ETD | V1: CURRENT EDT | W1: COMMENT | X1: STATUS | Y1: LEADTIME | Z1: REMARK | AA1: FCST | AB1: PO_ID
A2: =IF(B2="BUFKOR INC.","BUFKOR",IF(B2="CHIPPENHOOK","CHIPPENHOOK","SPECIALTY")) -> SPECIALTY | B2: {=IFERROR(XLOOKUP(G2&H2,SAP!K:K,SAP!A:A,0,0),"")} -> BUFKOR INC- | C2: =IFERROR(IF(OR('MASTER PLAN'!$B$2:$B$81="CHIPPENHOOK",'MASTER PLAN'!$B$2:$B$81="BUFKOR INC."),"USA",IF('MASTER PLAN'!$B$2:$B$81="SIGMAQ MEXICO S.A DE C.V","MX","SP")),"") -> SP | D2: RODNEY LLOYD | E2: =IFERROR(VLOOKUP(D2,REFERENCIAS!A:B,2,0),"") -> KENEDY TOBAR | F2: BOLSAS | G2: 1402048632 | H2: 10 | I2: {=IFERROR(XLOOKUP(G2&H2,SAP!K:K,SAP!D:D,0,0),"")} -> 10334816 | J2: {=UPPER(XLOOKUP(G2&H2,SAP!K:K,SAP!E:E,0,0))} -> BOLSA ROGERS ENTERPRISES 10"X4"X7-75" | K2: {=IFERROR(XLOOKUP(G2&H2,SAP!K:K,SAP!F:F,0,0),"")} -> 17500 | L2: {=IFERROR(XLOOKUP(G2&H2,SAP!K:K,SAP!G:G,0,0),"")} -> 18620 | M2: =IFERROR(L2/K2,0) -> 1.064 | N2: 0.2 | O2: =IFERROR(K2*(1+N2),0) -> 21000 | P2: 3316830 | Q2: 45835 | R2: {=IFERROR(XLOOKUP(G2&H2,SAP!K:K,SAP!H:H,0,0),"")} -> 45771 | S2: {=IFERROR(XLOOKUP(G2&H2,SAP!K:K,SAP!I:I,0,0),"")} -> 45838 | T2: 3000106444 | U2: 46038 | W2: ETA 24-Nov | X2: =IF(OR(U2<>0,V2<>0),"SCHEDULE","PENDING") -> SCHEDULE | Y2: =IF(U2<>0,IF(V2<>0,(V2-R2)/7,(U2-R2)/7),"") -> 38.142857 | Z2: =IF(Y2="","",IF(F2="BOLSAS",IF(Y2<=6,"IN TIME","DELAYED"),IF(F2="CAJAS",IF(Y2<=8,"IN TIME","DELAYED"),IF(Y2<=6,"IN TIME","DELAYED")))) -> DELAYED | AA2: =IF(AND(ISBLANK(U2),ISBLANK(V2)),"",IF(ISBLANK(V2),U2,V2)) -> 46038 | AB2: =CONCAT(G2,H2) -> 140204863210
A3: =IF(B3="BUFKOR INC.","BUFKOR",IF(B3="CHIPPENHOOK","CHIPPENHOOK","SPECIALTY")) -> SPECIALTY | B3: {=IFERROR(XLOOKUP(G3&H3,SAP!K:K,SAP!A:A,0,0),"")} -> BUFKOR INC- | C3: =IFERROR(IF(OR('MASTER PLAN'!$B$2:$B$81="CHIPPENHOOK",'MASTER PLAN'!$B$2:$B$81="BUFKOR INC."),"USA",IF('MASTER PLAN'!$B$2:$B$81="SIGMAQ MEXICO S.A DE C.V","MX","SP")),"") -> SP | D3: RODNEY LLOYD | E3: =IFERROR(VLOOKUP(D3,REFERENCIAS!A:B,2,0),"") -> KENEDY TOBAR | F3: BOLSAS | G3: 1402048797 | H3: 10 | I3: {=IFERROR(XLOOKUP(G3&H3,SAP!K:K,SAP!D:D,0,0),"")} -> 10335265 | J3: {=UPPER(XLOOKUP(G3&H3,SAP!K:K,SAP!E:E,0,0))} -> BOLSA MAUI DIVERS 8"X5"X8" | K3: {=IFERROR(XLOOKUP(G3&H3,SAP!K:K,SAP!F:F,0,0),"")} -> 1280 | L3: {=IFERROR(XLOOKUP(G3&H3,SAP!K:K,SAP!G:G,0,0),"")} -> 1730.56 | M3: =IFERROR(L3/K3,0) -> 1.352 | N3: 0.2 | O3: =IFERROR(K3*(1+N3),0) -> 1536 | P3: 3321183 | Q3: 45835 | R3: {=IFERROR(XLOOKUP(G3&H3,SAP!K:K,SAP!H:H,0,0),"")} -> 45806 | S3: {=IFERROR(XLOOKUP(G3&H3,SAP!K:K,SAP!I:I,0,0),"")} -> 45849 | U3: 45978 | X3: =IF(OR(U3<>0,V3<>0),"SCHEDULE","PENDING") -> SCHEDULE | Y3: =IF(U3<>0,IF(V3<>0,(V3-R3)/7,(U3-R3)/7),"") -> 24.571429 | Z3: =IF(Y3="","",IF(F3="BOLSAS",IF(Y3<=6,"IN TIME","DELAYED"),IF(F3="CAJAS",IF(Y3<=8,"IN TIME","DELAYED"),IF(Y3<=6,"IN TIME","DELAYED")))) -> DELAYED | AA3: =IF(AND(ISBLANK(U3),ISBLANK(V3)),"",IF(ISBLANK(V3),U3,V3)) -> 45978 | AB3: =CONCAT(G3,H3) -> 140204879710
A4: =IF(B4="BUFKOR INC.","BUFKOR",IF(B4="CHIPPENHOOK","CHIPPENHOOK","SPECIALTY")) -> CHIPPENHOOK | B4: {=IFERROR(XLOOKUP(G4&H4,SAP!K:K,SAP!A:A,0,0),"")} -> CHIPPENHOOK | C4: =IFERROR(IF(OR('MASTER PLAN'!$B$2:$B$81="CHIPPENHOOK",'MASTER PLAN'!$B$2:$B$81="BUFKOR INC."),"USA",IF('MASTER PLAN'!$B$2:$B$81="SIGMAQ MEXICO S.A DE C.V","MX","SP")),"") -> USA | D4: PAUL POMROY | E4: =IFERROR(VLOOKUP(D4,REFERENCIAS!A:B,2,0),"") -> SANTOS CORNEJO | F4: BOLSAS | G4: 1402048824 | H4: 10 | I4: {=IFERROR(XLOOKUP(G4&H4,SAP!K:K,SAP!D:D,0,0),"")} -> 10332711 | J4: {=UPPER(XLOOKUP(G4&H4,SAP!K:K,SAP!E:E,0,0))} -> BOLSA FRED MEYER 4-5"X3"X5-5" | K4: {=IFERROR(XLOOKUP(G4&H4,SAP!K:K,SAP!F:F,0,0),"")} -> 16704 | L4: {=IFERROR(XLOOKUP(G4&H4,SAP!K:K,SAP!G:G,0,0),"")} -> 5178.24 | M4: =IFERROR(L4/K4,0) -> 0.31 | N4: 0.2 | O4: =IFERROR(K4*(1+N4),0) -> 20044.8 | P4: 3323155 | Q4: 45835 | R4: {=IFERROR(XLOOKUP(G4&H4,SAP!K:K,SAP!H:H,0,0),"")} -> 45814 | S4: {=IFERROR(XLOOKUP(G4&H4,SAP!K:K,SAP!I:I,0,0),"")} -> 45877 | U4: 45946 | X4: =IF(OR(U4<>0,V4<>0),"SCHEDULE","PENDING") -> SCHEDULE | Y4: =IF(U4<>0,IF(V4<>0,(V4-R4)/7,(U4-R4)/7),"") -> 18.857143 | Z4: =IF(Y4="","",IF(F4="BOLSAS",IF(Y4<=6,"IN TIME","DELAYED"),IF(F4="CAJAS",IF(Y4<=8,"IN TIME","DELAYED"),IF(Y4<=6,"IN TIME","DELAYED")))) -> DELAYED | AA4: =IF(AND(ISBLANK(U4),ISBLANK(V4)),"",IF(ISBLANK(V4),U4,V4)) -> 45946 | AB4: =CONCAT(G4,H4) -> 140204882410
A5: =IF(B5="BUFKOR INC.","BUFKOR",IF(B5="CHIPPENHOOK","CHIPPENHOOK","SPECIALTY")) -> CHIPPENHOOK | B5: {=IFERROR(XLOOKUP(G5&H5,SAP!K:K,SAP!A:A,0,0),"")} -> CHIPPENHOOK | C5: =IFERROR(IF(OR('MASTER PLAN'!$B$2:$B$81="CHIPPENHOOK",'MASTER PLAN'!$B$2:$B$81="BUFKOR INC."),"USA",IF('MASTER PLAN'!$B$2:$B$81="SIGMAQ MEXICO S.A DE C.V","MX","SP")),"") -> USA | D5: PAUL POMROY | E5: =IFERROR(VLOOKUP(D5,REFERENCIAS!A:B,2,0),"") -> SANTOS CORNEJO | F5: BOLSAS | G5: 1402048833 | H5: 10 | I5: {=IFERROR(XLOOKUP(G5&H5,SAP!K:K,SAP!D:D,0,0),"")} -> 10332711 | J5: {=UPPER(XLOOKUP(G5&H5,SAP!K:K,SAP!E:E,0,0))} -> BOLSA FRED MEYER 4-5"X3"X5-5" | K5: {=IFERROR(XLOOKUP(G5&H5,SAP!K:K,SAP!F:F,0,0),"")} -> 54180 | L5: {=IFERROR(XLOOKUP(G5&H5,SAP!K:K,SAP!G:G,0,0),"")} -> 27509.4 | M5: =IFERROR(L5/K5,0) -> 0.50774086 | N5: 0.1 | O5: =IFERROR(K5*(1+N5),0) -> 59598 | P5: 3326351 | Q5: 45845 | R5: {=IFERROR(XLOOKUP(G5&H5,SAP!K:K,SAP!H:H,0,0),"")} -> 45814 | S5: {=IFERROR(XLOOKUP(G5&H5,SAP!K:K,SAP!I:I,0,0),"")} -> 45982 | W5: Línea externa Melissa. | X5: =IF(OR(U5<>0,V5<>0),"SCHEDULE","PENDING") -> PENDING | Y5: =IF(U5<>0,IF(V5<>0,(V5-R5)/7,(U5-R5)/7),"") | Z5: =IF(Y5="","",IF(F5="BOLSAS",IF(Y5<=6,"IN TIME","DELAYED"),IF(F5="CAJAS",IF(Y5<=8,"IN TIME","DELAYED"),IF(Y5<=6,"IN TIME","DELAYED")))) | AA5: =IF(AND(ISBLANK(U5),ISBLANK(V5)),"",IF(ISBLANK(V5),U5,V5)) | AB5: =CONCAT(G5,H5) -> 140204883310
A6: =IF(B6="BUFKOR INC.","BUFKOR",IF(B6="CHIPPENHOOK","CHIPPENHOOK","SPECIALTY")) -> CHIPPENHOOK | B6: {=IFERROR(XLOOKUP(G6&H6,SAP!K:K,SAP!A:A,0,0),"")} -> CHIPPENHOOK | C6: =IFERROR(IF(OR('MASTER PLAN'!$B$2:$B$81="CHIPPENHOOK",'MASTER PLAN'!$B$2:$B$81="BUFKOR INC."),"USA",IF('MASTER PLAN'!$B$2:$B$81="SIGMAQ MEXICO S.A DE C.V","MX","SP")),"") -> USA | D6: PAUL POMROY | E6: =IFERROR(VLOOKUP(D6,REFERENCIAS!A:B,2,0),"") -> SANTOS CORNEJO | F6: BOLSAS | G6: 1402048833 | H6: 20 | I6: {=IFERROR(XLOOKUP(G6&H6,SAP!K:K,SAP!D:D,0,0),"")} -> 10332712 | J6: {=UPPER(XLOOKUP(G6&H6,SAP!K:K,SAP!E:E,0,0))} -> BOLSA FRED MEYER 10"X4"X8" | K6: {=IFERROR(XLOOKUP(G6&H6,SAP!K:K,SAP!F:F,0,0),"")} -> 6240 | L6: {=IFERROR(XLOOKUP(G6&H6,SAP!K:K,SAP!G:G,0,0),"")} -> 3931.2 | M6: =IFERROR(L6/K6,0) -> 0.63 | N6: 0.1 | O6: =IFERROR(K6*(1+N6),0) -> 6864 | P6: 3326351 | Q6: 45845 | R6: {=IFERROR(XLOOKUP(G6&H6,SAP!K:K,SAP!H:H,0,0),"")} -> 45814 | S6: {=IFERROR(XLOOKUP(G6&H6,SAP!K:K,SAP!I:I,0,0),"")} -> 45982 | U6: 45974 | X6: =IF(OR(U6<>0,V6<>0),"SCHEDULE","PENDING") -> SCHEDULE | Y6: =IF(U6<>0,IF(V6<>0,(V6-R6)/7,(U6-R6)/7),"") -> 22.857143 | Z6: =IF(Y6="","",IF(F6="BOLSAS",IF(Y6<=6,"IN TIME","DELAYED"),IF(F6="CAJAS",IF(Y6<=8,"IN TIME","DELAYED"),IF(Y6<=6,"IN TIME","DELAYED")))) -> DELAYED | AA6: =IF(AND(ISBLANK(U6),ISBLANK(V6)),"",IF(ISBLANK(V6),U6,V6)) -> 45974 | AB6: =CONCAT(G6,H6) -> 140204883320
A7: =IF(B7="BUFKOR INC.","BUFKOR",IF(B7="CHIPPENHOOK","CHIPPENHOOK","SPECIALTY")) -> SPECIALTY | B7: {=IFERROR(XLOOKUP(G7&H7,SAP!K:K,SAP!A:A,0,0),"")} -> BUFKOR INC- | C7: =IFERROR(IF(OR('MASTER PLAN'!$B$2:$B$81="CHIPPENHOOK",'MASTER PLAN'!$B$2:$B$81="BUFKOR INC."),"USA",IF('MASTER PLAN'!$B$2:$B$81="SIGMAQ MEXICO S.A DE C.V","MX","SP")),"") -> SP | D7: JENNIFER BEAGLE | E7: =IFERROR(VLOOKUP(D7,REFERENCIAS!A:B,2,0),"") -> JAVIER MOLINA | F7: BOLSAS | G7: 1402049194 | H7: 10 | I7: {=IFERROR(XLOOKUP(G7&H7,SAP!K:K,SAP!D:D,0,0),"")} -> 10330512 | J7: {=UPPER(XLOOKUP(G7&H7,SAP!K:K,SAP!E:E,0,0))} -> BOLSA ALMAGEN CORP 8"X4"X10" | K7: {=IFERROR(XLOOKUP(G7&H7,SAP!K:K,SAP!F:F,0,0),"")} -> 2000 | L7: {=IFERROR(XLOOKUP(G7&H7,SAP!K:K,SAP!G:G,0,0),"")} -> 5856 | M7: =IFERROR(L7/K7,0) -> 2.928 | N7: 0.2 | O7: =IFERROR(K7*(1+N7),0) -> 2400 | P7: 3337498 | Q7: 45903 | R7: {=IFERROR(XLOOKUP(G7&H7,SAP!K:K,SAP!H:H,0,0),"")} -> 45923 | S7: {=IFERROR(XLOOKUP(G7&H7,SAP!K:K,SAP!I:I,0,0),"")} -> 45931 | U7: 45986 | X7: =IF(OR(U7<>0,V7<>0),"SCHEDULE","PENDING") -> SCHEDULE | Y7: =IF(U7<>0,IF(V7<>0,(V7-R7)/7,(U7-R7)/7),"") -> 9 | Z7: =IF(Y7="","",IF(F7="BOLSAS",IF(Y7<=6,"IN TIME","DELAYED"),IF(F7="CAJAS",IF(Y7<=8,"IN TIME","DELAYED"),IF(Y7<=6,"IN TIME","DELAYED")))) -> DELAYED | AA7: =IF(AND(ISBLANK(U7),ISBLANK(V7)),"",IF(ISBLANK(V7),U7,V7)) -> 45986 | AB7: =CONCAT(G7,H7) -> 140204919410
A8: =IF(B8="BUFKOR INC.","BUFKOR",IF(B8="CHIPPENHOOK","CHIPPENHOOK","SPECIALTY")) -> SPECIALTY | B8: {=IFERROR(XLOOKUP(G8&H8,SAP!K:K,SAP!A:A,0,0),"")} -> BUFKOR INC- | C8: =IFERROR(IF(OR('MASTER PLAN'!$B$2:$B$81="CHIPPENHOOK",'MASTER PLAN'!$B$2:$B$81="BUFKOR INC."),"USA",IF('MASTER PLAN'!$B$2:$B$81="SIGMAQ MEXICO S.A DE C.V","MX","SP")),"") -> SP | D8: SAM JONHSTON | E8: =IFERROR(VLOOKUP(D8,REFERENCIAS!A:B,2,0),"") -> ASHLY MERINO | F8: BOLSAS | G8: 1402049207 | H8: 10 | I8: {=IFERROR(XLOOKUP(G8&H8,SAP!K:K,SAP!D:D,0,0),"")} -> 10271087 | J8: {=UPPER(XLOOKUP(G8&H8,SAP!K:K,SAP!E:E,0,0))} -> BOLSA FINKS JEWELERS 6-5"X3-5"X6-5" | K8: {=IFERROR(XLOOKUP(G8&H8,SAP!K:K,SAP!F:F,0,0),"")} -> 9000 | L8: {=IFERROR(XLOOKUP(G8&H8,SAP!K:K,SAP!G:G,0,0),"")} -> 5040 | M8: =IFERROR(L8/K8,0) -> 0.56 | N8: 0.2 | O8: =IFERROR(K8*(1+N8),0) -> 10800 | P8: 3336254 | Q8: 45896 | R8: {=IFERROR(XLOOKUP(G8&H8,SAP!K:K,SAP!H:H,0,0),"")} -> 45923 | S8: {=IFERROR(XLOOKUP(G8&H8,SAP!K:K,SAP!I:I,0,0),"")} -> 45894 | U8: 45993 | X8: =IF(OR(U8<>0,V8<>0),"SCHEDULE","PENDING") -> SCHEDULE | Y8: =IF(U8<>0,IF(V8<>0,(V8-R8)/7,(U8-R8)/7),"") -> 10 | Z8: =IF(Y8="","",IF(F8="BOLSAS",IF(Y8<=6,"IN TIME","DELAYED"),IF(F8="CAJAS",IF(Y8<=8,"IN TIME","DELAYED"),IF(Y8<=6,"IN TIME","DELAYED")))) -> DELAYED | AA8: =IF(AND(ISBLANK(U8),ISBLANK(V8)),"",IF(ISBLANK(V8),U8,V8)) -> 45993 | AB8: =CONCAT(G8,H8) -> 140204920710
A9: =IF(B9="BUFKOR INC.","BUFKOR",IF(B9="CHIPPENHOOK","CHIPPENHOOK","SPECIALTY")) -> SPECIALTY | B9: {=IFERROR(XLOOKUP(G9&H9,SAP!K:K,SAP!A:A,0,0),"")} -> BUFKOR INC- | C9: =IFERROR(IF(OR('MASTER PLAN'!$B$2:$B$81="CHIPPENHOOK",'MASTER PLAN'!$B$2:$B$81="BUFKOR INC."),"USA",IF('MASTER PLAN'!$B$2:$B$81="SIGMAQ MEXICO S.A DE C.V","MX","SP")),"") -> SP | D9: SAM JONHSTON | E9: =IFERROR(VLOOKUP(D9,REFERENCIAS!A:B,2,0),"") -> ASHLY MERINO | F9: BOLSAS | G9: 1402049437 | H9: 10 | I9: {=IFERROR(XLOOKUP(G9&H9,SAP!K:K,SAP!D:D,0,0),"")} -> 10276560 | J9: {=UPPER(XLOOKUP(G9&H9,SAP!K:K,SAP!E:E,0,0))} -> BOLSA FINKS JWLS 10X5X10" | K9: {=IFERROR(XLOOKUP(G9&H9,SAP!K:K,SAP!F:F,0,0),"")} -> 3000 | L9: {=IFERROR(XLOOKUP(G9&H9,SAP!K:K,SAP!G:G,0,0),"")} -> 3528 | M9: =IFERROR(L9/K9,0) -> 1.176 | N9: 0.2 | O9: =IFERROR(K9*(1+N9),0) -> 3600 | P9: 3351135 | Q9: 45968 | R9: {=IFERROR(XLOOKUP(G9&H9,SAP!K:K,SAP!H:H,0,0),"")} -> 45940 | S9: {=IFERROR(XLOOKUP(G9&H9,SAP!K:K,SAP!I:I,0,0),"")} -> 45999 | T9: 3000117203 | W9: Línea externa Melissa. Sale PT de P3 el 15-Dic. | X9: =IF(OR(U9<>0,V9<>0),"SCHEDULE","PENDING") -> PENDING | Y9: =IF(U9<>0,IF(V9<>0,(V9-R9)/7,(U9-R9)/7),"") | Z9: =IF(Y9="","",IF(F9="BOLSAS",IF(Y9<=6,"IN TIME","DELAYED"),IF(F9="CAJAS",IF(Y9<=8,"IN TIME","DELAYED"),IF(Y9<=6,"IN TIME","DELAYED")))) | AA9: =IF(AND(ISBLANK(U9),ISBLANK(V9)),"",IF(ISBLANK(V9),U9,V9)) | AB9: =CONCAT(G9,H9) -> 140204943710
A10: =IF(B10="BUFKOR INC.","BUFKOR",IF(B10="CHIPPENHOOK","CHIPPENHOOK","SPECIALTY")) -> SPECIALTY | B10: {=IFERROR(XLOOKUP(G10&H10,SAP!K:K,SAP!A:A,0,0),"")} -> BUFKOR INC- | C10: =IFERROR(IF(OR('MASTER PLAN'!$B$2:$B$81="CHIPPENHOOK",'MASTER PLAN'!$B$2:$B$81="BUFKOR INC."),"USA",IF('MASTER PLAN'!$B$2:$B$81="SIGMAQ MEXICO S.A DE C.V","MX","SP")),"") -> SP | D10: SAM JONHSTON | E10: =IFERROR(VLOOKUP(D10,REFERENCIAS!A:B,2,0),"") -> ASHLY MERINO | F10: BOLSAS | G10: 1402049207 | H10: 20 | I10: {=IFERROR(XLOOKUP(G10&H10,SAP!K:K,SAP!D:D,0,0),"")} -> 10271097 | J10: {=UPPER(XLOOKUP(G10&H10,SAP!K:K,SAP!E:E,0,0))} -> BOLSA FINKS JEWELERS 7"X5"X9" | K10: {=IFERROR(XLOOKUP(G10&H10,SAP!K:K,SAP!F:F,0,0),"")} -> 12000 | L10: {=IFERROR(XLOOKUP(G10&H10,SAP!K:K,SAP!G:G,0,0),"")} -> 8736 | M10: =IFERROR(L10/K10,0) -> 0.728 | N10: 0.2 | O10: =IFERROR(K10*(1+N10),0) -> 14400 | P10: 3336254 | Q10: 45896 | R10: {=IFERROR(XLOOKUP(G10&H10,SAP!K:K,SAP!H:H,0,0),"")} -> 45923 | S10: {=IFERROR(XLOOKUP(G10&H10,SAP!K:K,SAP!I:I,0,0),"")} -> 45894 | U10: 46000 | W10: Línea Externa Melissa 7,500 unidades. | X10: =IF(OR(U10<>0,V10<>0),"SCHEDULE","PENDING") -> SCHEDULE | Y10: =IF(U10<>0,IF(V10<>0,(V10-R10)/7,(U10-R10)/7),"") -> 11 | Z10: =IF(Y10="","",IF(F10="BOLSAS",IF(Y10<=6,"IN TIME","DELAYED"),IF(F10="CAJAS",IF(Y10<=8,"IN TIME","DELAYED"),IF(Y10<=6,"IN TIME","DELAYED")))) -> DELAYED | AA10: =IF(AND(ISBLANK(U10),ISBLANK(V10)),"",IF(ISBLANK(V10),U10,V10)) -> 46000 | AB10: =CONCAT(G10,H10) -> 140204920720
A11: =IF(B11="BUFKOR INC.","BUFKOR",IF(B11="CHIPPENHOOK","CHIPPENHOOK","SPECIALTY")) -> SPECIALTY | B11: {=IFERROR(XLOOKUP(G11&H11,SAP!K:K,SAP!A:A,0,0),"")} -> BUFKOR INC- | C11: =IFERROR(IF(OR('MASTER PLAN'!$B$2:$B$81="CHIPPENHOOK",'MASTER PLAN'!$B$2:$B$81="BUFKOR INC."),"USA",IF('MASTER PLAN'!$B$2:$B$81="SIGMAQ MEXICO S.A DE C.V","MX","SP")),"") -> SP | D11: RODNEY LLOYD | E11: =IFERROR(VLOOKUP(D11,REFERENCIAS!A:B,2,0),"") -> KENEDY TOBAR | F11: BOLSAS | G11: 1402049238 | H11: 10 | I11: {=IFERROR(XLOOKUP(G11&H11,SAP!K:K,SAP!D:D,0,0),"")} -> 10335266 | J11: {=UPPER(XLOOKUP(G11&H11,SAP!K:K,SAP!E:E,0,0))} -> BOLSA MAUI DIVERS 10"X6"X10" | K11: {=IFERROR(XLOOKUP(G11&H11,SAP!K:K,SAP!F:F,0,0),"")} -> 3040 | L11: {=IFERROR(XLOOKUP(G11&H11,SAP!K:K,SAP!G:G,0,0),"")} -> 5496.32 | M11: =IFERROR(L11/K11,0) -> 1.808 | N11: 0.2 | O11: =IFERROR(K11*(1+N11),0) -> 3648 | P11: 3341642 | Q11: 45922 | R11: {=IFERROR(XLOOKUP(G11&H11,SAP!K:K,SAP!H:H,0,0),"")} -> 45918 | S11: {=IFERROR(XLOOKUP(G11&H11,SAP!K:K,SAP!I:I,0,0),"")} -> 45960 | U11: 45973 | X11: =IF(OR(U11<>0,V11<>0),"SCHEDULE","PENDING") -> SCHEDULE | Y11: =IF(U11<>0,IF(V11<>0,(V11-R11)/7,(U11-R11)/7),"") -> 7.8571429 | Z11: =IF(Y11="","",IF(F11="BOLSAS",IF(Y11<=6,"IN TIME","DELAYED"),IF(F11="CAJAS",IF(Y11<=8,"IN TIME","DELAYED"),IF(Y11<=6,"IN TIME","DELAYED")))) -> DELAYED | AA11: =IF(AND(ISBLANK(U11),ISBLANK(V11)),"",IF(ISBLANK(V11),U11,V11)) -> 45973 | AB11: =CONCAT(G11,H11) -> 140204923810
A12: =IF(B12="BUFKOR INC.","BUFKOR",IF(B12="CHIPPENHOOK","CHIPPENHOOK","SPECIALTY")) -> SPECIALTY | B12: {=IFERROR(XLOOKUP(G12&H12,SAP!K:K,SAP!A:A,0,0),"")} -> BUFKOR INC- | C12: =IFERROR(IF(OR('MASTER PLAN'!$B$2:$B$81="CHIPPENHOOK",'MASTER PLAN'!$B$2:$B$81="BUFKOR INC."),"USA",IF('MASTER PLAN'!$B$2:$B$81="SIGMAQ MEXICO S.A DE C.V","MX","SP")),"") -> SP | D12: ENOC MADRIL | E12: =IFERROR(VLOOKUP(D12,REFERENCIAS!A:B,2,0),"") -> REYNALDO CARRANZA | F12: BOLSAS | G12: 1402049263 | H12: 10 | I12: {=IFERROR(XLOOKUP(G12&H12,SAP!K:K,SAP!D:D,0,0),"")} -> 10269533 | J12: {=UPPER(XLOOKUP(G12&H12,SAP!K:K,SAP!E:E,0,0))} -> FOLDER GOLD CASTER LAWRENCE | K12: {=IFERROR(XLOOKUP(G12&H12,SAP!K:K,SAP!F:F,0,0),"")} -> 3000 | L12: {=IFERROR(XLOOKUP(G12&H12,SAP!K:K,SAP!G:G,0,0),"")} -> 2415 | M12: =IFERROR(L12/K12,0) -> 0.805 | N12: 0.2 | O12: =IFERROR(K12*(1+N12),0) -> 3600 | P12: 3341644 | Q12: 45922 | R12: {=IFERROR(XLOOKUP(G12&H12,SAP!K:K,SAP!H:H,0,0),"")} -> 45918 | S12: {=IFERROR(XLOOKUP(G12&H12,SAP!K:K,SAP!I:I,0,0),"")} -> 45961 | U12: 46000 | W12: Falta programar 1,000 unidades. | X12: =IF(OR(U12<>0,V12<>0),"SCHEDULE","PENDING") -> SCHEDULE | Y12: =IF(U12<>0,IF(V12<>0,(V12-R12)/7,(U12-R12)/7),"") -> 11.714286 | Z12: =IF(Y12="","",IF(F12="BOLSAS",IF(Y12<=6,"IN TIME","DELAYED"),IF(F12="CAJAS",IF(Y12<=8,"IN TIME","DELAYED"),IF(Y12<=6,"IN TIME","DELAYED")))) -> DELAYED | AA12: =IF(AND(ISBLANK(U12),ISBLANK(V12)),"",IF(ISBLANK(V12),U12,V12)) -> 46000 | AB12: =CONCAT(G12,H12) -> 140204926310
A13: =IF(B13="BUFKOR INC.","BUFKOR",IF(B13="CHIPPENHOOK","CHIPPENHOOK","SPECIALTY")) -> SPECIALTY | B13: {=IFERROR(XLOOKUP(G13&H13,SAP!K:K,SAP!A:A,0,0),"")} -> BUFKOR INC- | C13: =IFERROR(IF(OR('MASTER PLAN'!$B$2:$B$81="CHIPPENHOOK",'MASTER PLAN'!$B$2:$B$81="BUFKOR INC."),"USA",IF('MASTER PLAN'!$B$2:$B$81="SIGMAQ MEXICO S.A DE C.V","MX","SP")),"") -> SP | D13: LYNDA MORRISON | E13: =IFERROR(VLOOKUP(D13,REFERENCIAS!A:B,2,0),"") -> LIGIA MONRROY | F13: BOLSAS | G13: 1402049277 | H13: 10 | I13: {=IFERROR(XLOOKUP(G13&H13,SAP!K:K,SAP!D:D,0,0),"")} -> 10341337 | J13: {=UPPER(XLOOKUP(G13&H13,SAP!K:K,SAP!E:E,0,0))} -> BOLSA ELEGANCE 8X4X10 IN FL | K13: {=IFERROR(XLOOKUP(G13&H13,SAP!K:K,SAP!F:F,0,0),"")} -> 5000 | L13: {=IFERROR(XLOOKUP(G13&H13,SAP!K:K,SAP!G:G,0,0),"")} -> 5480 | M13: =IFERROR(L13/K13,0) -> 1.096 | N13: 0.2 | O13: =IFERROR(K13*(1+N13),0) -> 6000 | P13: 3341646 | Q13: 45922 | R13: {=IFERROR(XLOOKUP(G13&H13,SAP!K:K,SAP!H:H,0,0),"")} -> 45918 | S13: {=IFERROR(XLOOKUP(G13&H13,SAP!K:K,SAP!I:I,0,0),"")} -> 45940 | U13: 45986 | X13: =IF(OR(U13<>0,V13<>0),"SCHEDULE","PENDING") -> SCHEDULE | Y13: =IF(U13<>0,IF(V13<>0,(V13-R13)/7,(U13-R13)/7),"") -> 9.7142857 | Z13: =IF(Y13="","",IF(F13="BOLSAS",IF(Y13<=6,"IN TIME","DELAYED"),IF(F13="CAJAS",IF(Y13<=8,"IN TIME","DELAYED"),IF(Y13<=6,"IN TIME","DELAYED")))) -> DELAYED | AA13: =IF(AND(ISBLANK(U13),ISBLANK(V13)),"",IF(ISBLANK(V13),U13,V13)) -> 45986 | AB13: =CONCAT(G13,H13) -> 140204927710
A14: =IF(B14="BUFKOR INC.","BUFKOR",IF(B14="CHIPPENHOOK","CHIPPENHOOK","SPECIALTY")) -> SPECIALTY | B14: {=IFERROR(XLOOKUP(G14&H14,SAP!K:K,SAP!A:A,0,0),"")} -> BUFKOR INC- | C14: =IFERROR(IF(OR('MASTER PLAN'!$B$2:$B$81="CHIPPENHOOK",'MASTER PLAN'!$B$2:$B$81="BUFKOR INC."),"USA",IF('MASTER PLAN'!$B$2:$B$81="SIGMAQ MEXICO S.A DE C.V","MX","SP")),"") -> SP | D14: LYNDA MORRISON | E14: =IFERROR(VLOOKUP(D14,REFERENCIAS!A:B,2,0),"") -> LIGIA MONRROY | F14: BOLSAS | G14: 1402049277 | H14: 20 | I14: {=IFERROR(XLOOKUP(G14&H14,SAP!K:K,SAP!D:D,0,0),"")} -> 10341336 | J14: {=UPPER(XLOOKUP(G14&H14,SAP!K:K,SAP!E:E,0,0))} -> BOLSA ELEGANCE 6-5X3-5X6-5 IN FL | K14: {=IFERROR(XLOOKUP(G14&H14,SAP!K:K,SAP!F:F,0,0),"")} -> 5000 | L14: {=IFERROR(XLOOKUP(G14&H14,SAP!K:K,SAP!G:G,0,0),"")} -> 4440 | M14: =IFERROR(L14/K14,0) -> 0.888 | N14: 0.2 | O14: =IFERROR(K14*(1+N14),0) -> 6000 | P14: 3341647 | Q14: 45922 | R14: {=IFERROR(XLOOKUP(G14&H14,SAP!K:K,SAP!H:H,0,0),"")} -> 45918 | S14: {=IFERROR(XLOOKUP(G14&H14,SAP!K:K,SAP!I:I,0,0),"")} -> 45940 | U14: 45986 | W14: Se despacharon 600 unidades aéreas. | X14: =IF(OR(U14<>0,V14<>0),"SCHEDULE","PENDING") -> SCHEDULE | Y14: =IF(U14<>0,IF(V14<>0,(V14-R14)/7,(U14-R14)/7),"") -> 9.7142857 | Z14: =IF(Y14="","",IF(F14="BOLSAS",IF(Y14<=6,"IN TIME","DELAYED"),IF(F14="CAJAS",IF(Y14<=8,"IN TIME","DELAYED"),IF(Y14<=6,"IN TIME","DELAYED")))) -> DELAYED | AA14: =IF(AND(ISBLANK(U14),ISBLANK(V14)),"",IF(ISBLANK(V14),U14,V14)) -> 45986 | AB14: =CONCAT(G14,H14) -> 140204927720
A15: =IF(B15="BUFKOR INC.","BUFKOR",IF(B15="CHIPPENHOOK","CHIPPENHOOK","SPECIALTY")) -> SPECIALTY | B15: {=IFERROR(XLOOKUP(G15&H15,SAP!K:K,SAP!A:A,0,0),"")} -> BUFKOR INC- | C15: =IFERROR(IF(OR('MASTER PLAN'!$B$2:$B$81="CHIPPENHOOK",'MASTER PLAN'!$B$2:$B$81="BUFKOR INC."),"USA",IF('MASTER PLAN'!$B$2:$B$81="SIGMAQ MEXICO S.A DE C.V","MX","SP")),"") -> SP | D15: LYNDA MORRISON | E15: =IFERROR(VLOOKUP(D15,REFERENCIAS!A:B,2,0),"") -> LIGIA MONRROY | F15: BOLSAS | G15: 1402049277 | H15: 30 | I15: {=IFERROR(XLOOKUP(G15&H15,SAP!K:K,SAP!D:D,0,0),"")} -> 10341335 | J15: {=UPPER(XLOOKUP(G15&H15,SAP!K:K,SAP!E:E,0,0))} -> BOLSA ELEGANCE 4-5X2-5X5-75 IN FL | K15: {=IFERROR(XLOOKUP(G15&H15,SAP!K:K,SAP!F:F,0,0),"")} -> 5000 | L15: {=IFERROR(XLOOKUP(G15&H15,SAP!K:K,SAP!G:G,0,0),"")} -> 4080 | M15: =IFERROR(L15/K15,0) -> 0.816 | N15: 0.2 | O15: =IFERROR(K15*(1+N15),0) -> 6000 | P15: 3341648 | Q15: 45922 | R15: {=IFERROR(XLOOKUP(G15&H15,SAP!K:K,SAP!H:H,0,0),"")} -> 45918 | S15: {=IFERROR(XLOOKUP(G15&H15,SAP!K:K,SAP!I:I,0,0),"")} -> 45940 | U15: 45986 | W15: Se despacharon 900 unidades aéreas. | X15: =IF(OR(U15<>0,V15<>0),"SCHEDULE","PENDING") -> SCHEDULE | Y15: =IF(U15<>0,IF(V15<>0,(V15-R15)/7,(U15-R15)/7),"") -> 9.7142857 | Z15: =IF(Y15="","",IF(F15="BOLSAS",IF(Y15<=6,"IN TIME","DELAYED"),IF(F15="CAJAS",IF(Y15<=8,"IN TIME","DELAYED"),IF(Y15<=6,"IN TIME","DELAYED")))) -> DELAYED | AA15: =IF(AND(ISBLANK(U15),ISBLANK(V15)),"",IF(ISBLANK(V15),U15,V15)) -> 45986 | AB15: =CONCAT(G15,H15) -> 140204927730
A16: =IF(B16="BUFKOR INC.","BUFKOR",IF(B16="CHIPPENHOOK","CHIPPENHOOK","SPECIALTY")) -> SPECIALTY | B16: {=IFERROR(XLOOKUP(G16&H16,SAP!K:K,SAP!A:A,0,0),"")} -> BUFKOR INC- | C16: =IFERROR(IF(OR('MASTER PLAN'!$B$2:$B$81="CHIPPENHOOK",'MASTER PLAN'!$B$2:$B$81="BUFKOR INC."),"USA",IF('MASTER PLAN'!$B$2:$B$81="SIGMAQ MEXICO S.A DE C.V","MX","SP")),"") -> SP | D16: LYNDA MORRISON | E16: =IFERROR(VLOOKUP(D16,REFERENCIAS!A:B,2,0),"") -> LIGIA MONRROY | F16: BOLSAS | G16: 1402049277 | H16: 40 | I16: {=IFERROR(XLOOKUP(G16&H16,SAP!K:K,SAP!D:D,0,0),"")} -> 10341338 | J16: {=UPPER(XLOOKUP(G16&H16,SAP!K:K,SAP!E:E,0,0))} -> BOLSA ELEGANCE 12-5X4X14 IN FL | K16: {=IFERROR(XLOOKUP(G16&H16,SAP!K:K,SAP!F:F,0,0),"")} -> 3000 | L16: {=IFERROR(XLOOKUP(G16&H16,SAP!K:K,SAP!G:G,0,0),"")} -> 5496 | M16: =IFERROR(L16/K16,0) -> 1.832 | N16: 0.2 | O16: =IFERROR(K16*(1+N16),0) -> 3600 | P16: 3341650 | Q16: 45922 | R16: {=IFERROR(XLOOKUP(G16&H16,SAP!K:K,SAP!H:H,0,0),"")} -> 45918 | S16: {=IFERROR(XLOOKUP(G16&H16,SAP!K:K,SAP!I:I,0,0),"")} -> 45940 | U16: 45993 | X16: =IF(OR(U16<>0,V16<>0),"SCHEDULE","PENDING") -> SCHEDULE | Y16: =IF(U16<>0,IF(V16<>0,(V16-R16)/7,(U16-R16)/7),"") -> 10.714286 | Z16: =IF(Y16="","",IF(F16="BOLSAS",IF(Y16<=6,"IN TIME","DELAYED"),IF(F16="CAJAS",IF(Y16<=8,"IN TIME","DELAYED"),IF(Y16<=6,"IN TIME","DELAYED")))) -> DELAYED | AA16: =IF(AND(ISBLANK(U16),ISBLANK(V16)),"",IF(ISBLANK(V16),U16,V16)) -> 45993 | AB16: =CONCAT(G16,H16) -> 140204927740
A17: =IF(B17="BUFKOR INC.","BUFKOR",IF(B17="CHIPPENHOOK","CHIPPENHOOK","SPECIALTY")) -> SPECIALTY | B17: {=IFERROR(XLOOKUP(G17&H17,SAP!K:K,SAP!A:A,0,0),"")} -> BUFKOR INC- | C17: =IFERROR(IF(OR('MASTER PLAN'!$B$2:$B$81="CHIPPENHOOK",'MASTER PLAN'!$B$2:$B$81="BUFKOR INC."),"USA",IF('MASTER PLAN'!$B$2:$B$81="SIGMAQ MEXICO S.A DE C.V","MX","SP")),"") -> SP | D17: RODNEY LLOYD | E17: =IFERROR(VLOOKUP(D17,REFERENCIAS!A:B,2,0),"") -> KENEDY TOBAR | F17: BOLSAS | G17: 1402049281 | H17: 10 | I17: {=IFERROR(XLOOKUP(G17&H17,SAP!K:K,SAP!D:D,0,0),"")} -> 10335262 | J17: {=UPPER(XLOOKUP(G17&H17,SAP!K:K,SAP!E:E,0,0))} -> BOLSA ALBERTS JEWELERS 6-5"X3-5"X6-5" | K17: {=IFERROR(XLOOKUP(G17&H17,SAP!K:K,SAP!F:F,0,0),"")} -> 3500 | L17: {=IFERROR(XLOOKUP(G17&H17,SAP!K:K,SAP!G:G,0,0),"")} -> 3192 | M17: =IFERROR(L17/K17,0) -> 0.912 | N17: 0.2 | O17: =IFERROR(K17*(1+N17),0) -> 4200 | P17: 3341651 | Q17: 45922 | R17: {=IFERROR(XLOOKUP(G17&H17,SAP!K:K,SAP!H:H,0,0),"")} -> 45918 | S17: {=IFERROR(XLOOKUP(G17&H17,SAP!K:K,SAP!I:I,0,0),"")} -> 45961 | U17: 45986 | X17: =IF(OR(U17<>0,V17<>0),"SCHEDULE","PENDING") -> SCHEDULE | Y17: =IF(U17<>0,IF(V17<>0,(V17-R17)/7,(U17-R17)/7),"") -> 9.7142857 | Z17: =IF(Y17="","",IF(F17="BOLSAS",IF(Y17<=6,"IN TIME","DELAYED"),IF(F17="CAJAS",IF(Y17<=8,"IN TIME","DELAYED"),IF(Y17<=6,"IN TIME","DELAYED")))) -> DELAYED | AA17: =IF(AND(ISBLANK(U17),ISBLANK(V17)),"",IF(ISBLANK(V17),U17,V17)) -> 45986 | AB17: =CONCAT(G17,H17) -> 140204928110
A18: =IF(B18="BUFKOR INC.","BUFKOR",IF(B18="CHIPPENHOOK","CHIPPENHOOK","SPECIALTY")) -> SPECIALTY | B18: {=IFERROR(XLOOKUP(G18&H18,SAP!K:K,SAP!A:A,0,0),"")} -> BUFKOR INC- | C18: =IFERROR(IF(OR('MASTER PLAN'!$B$2:$B$81="CHIPPENHOOK",'MASTER PLAN'!$B$2:$B$81="BUFKOR INC."),"USA",IF('MASTER PLAN'!$B$2:$B$81="SIGMAQ MEXICO S.A DE C.V","MX","SP")),"") -> SP | D18: RODNEY LLOYD | E18: =IFERROR(VLOOKUP(D18,REFERENCIAS!A:B,2,0),"") -> KENEDY TOBAR | F18: BOLSAS | G18: 1402049281 | H18: 20 | I18: {=IFERROR(XLOOKUP(G18&H18,SAP!K:K,SAP!D:D,0,0),"")} -> 10340277 | J18: {=UPPER(XLOOKUP(G18&H18,SAP!K:K,SAP!E:E,0,0))} -> BOLSA ALBERTS JEWELERS 10"X6"X10" FL | K18: {=IFERROR(XLOOKUP(G18&H18,SAP!K:K,SAP!F:F,0,0),"")} -> 1200 | L18: {=IFERROR(XLOOKUP(G18&H18,SAP!K:K,SAP!G:G,0,0),"")} -> 1929.6 | M18: =IFERROR(L18/K18,0) -> 1.608 | N18: 0.2 | O18: =IFERROR(K18*(1+N18),0) -> 1440 | P18: 3341702 | Q18: 45922 | R18: {=IFERROR(XLOOKUP(G18&H18,SAP!K:K,SAP!H:H,0,0),"")} -> 45918 | S18: {=IFERROR(XLOOKUP(G18&H18,SAP!K:K,SAP!I:I,0,0),"")} -> 45961 | U18: 45986 | X18: =IF(OR(U18<>0,V18<>0),"SCHEDULE","PENDING") -> SCHEDULE | Y18: =IF(U18<>0,IF(V18<>0,(V18-R18)/7,(U18-R18)/7),"") -> 9.7142857 | Z18: =IF(Y18="","",IF(F18="BOLSAS",IF(Y18<=6,"IN TIME","DELAYED"),IF(F18="CAJAS",IF(Y18<=8,"IN TIME","DELAYED"),IF(Y18<=6,"IN TIME","DELAYED")))) -> DELAYED | AA18: =IF(AND(ISBLANK(U18),ISBLANK(V18)),"",IF(ISBLANK(V18),U18,V18)) -> 45986 | AB18: =CONCAT(G18,H18) -> 140204928120
A19: =IF(B19="BUFKOR INC.","BUFKOR",IF(B19="CHIPPENHOOK","CHIPPENHOOK","SPECIALTY")) -> SPECIALTY | B19: {=IFERROR(XLOOKUP(G19&H19,SAP!K:K,SAP!A:A,0,0),"")} -> BUFKOR INC- | C19: =IFERROR(IF(OR('MASTER PLAN'!$B$2:$B$81="CHIPPENHOOK",'MASTER PLAN'!$B$2:$B$81="BUFKOR INC."),"USA",IF('MASTER PLAN'!$B$2:$B$81="SIGMAQ MEXICO S.A DE C.V","MX","SP")),"") -> SP | D19: ROY DALE GUSHWA | E19: =IFERROR(VLOOKUP(D19,REFERENCIAS!A:B,2,0),"") -> REYNALDO CARRANZA | F19: BOLSAS | G19: 1402049286 | H19: 10 | I19: {=IFERROR(XLOOKUP(G19&H19,SAP!K:K,SAP!D:D,0,0),"")} -> 10315150 | J19: {=UPPER(XLOOKUP(G19&H19,SAP!K:K,SAP!E:E,0,0))} -> BOLSA HUNTINGTON 6-5"X3-5"X6-5" | K19: {=IFERROR(XLOOKUP(G19&H19,SAP!K:K,SAP!F:F,0,0),"")} -> 4500 | L19: {=IFERROR(XLOOKUP(G19&H19,SAP!K:K,SAP!G:G,0,0),"")} -> 7956 | M19: =IFERROR(L19/K19,0) -> 1.768 | N19: 0.2 | O19: =IFERROR(K19*(1+N19),0) -> 5400 | P19: 3341705 | Q19: 45922 | R19: {=IFERROR(XLOOKUP(G19&H19,SAP!K:K,SAP!H:H,0,0),"")} -> 45918 | S19: {=IFERROR(XLOOKUP(G19&H19,SAP!K:K,SAP!I:I,0,0),"")} -> 45945 | T19: 3000115091 | U19: 45993 | W19: ETA 10-Nov | X19: =IF(OR(U19<>0,V19<>0),"SCHEDULE","PENDING") -> SCHEDULE | Y19: =IF(U19<>0,IF(V19<>0,(V19-R19)/7,(U19-R19)/7),"") -> 10.714286 | Z19: =IF(Y19="","",IF(F19="BOLSAS",IF(Y19<=6,"IN TIME","DELAYED"),IF(F19="CAJAS",IF(Y19<=8,"IN TIME","DELAYED"),IF(Y19<=6,"IN TIME","DELAYED")))) -> DELAYED | AA19: =IF(AND(ISBLANK(U19),ISBLANK(V19)),"",IF(ISBLANK(V19),U19,V19)) -> 45993 | AB19: =CONCAT(G19,H19) -> 140204928610
A20: =IF(B20="BUFKOR INC.","BUFKOR",IF(B20="CHIPPENHOOK","CHIPPENHOOK","SPECIALTY")) -> SPECIALTY | B20: {=IFERROR(XLOOKUP(G20&H20,SAP!K:K,SAP!A:A,0,0),"")} -> BUFKOR INC- | C20: =IFERROR(IF(OR('MASTER PLAN'!$B$2:$B$81="CHIPPENHOOK",'MASTER PLAN'!$B$2:$B$81="BUFKOR INC."),"USA",IF('MASTER PLAN'!$B$2:$B$81="SIGMAQ MEXICO S.A DE C.V","MX","SP")),"") -> SP | D20: ROY DALE GUSHWA | E20: =IFERROR(VLOOKUP(D20,REFERENCIAS!A:B,2,0),"") -> REYNALDO CARRANZA | F20: BOLSAS | G20: 1402049286 | H20: 20 | I20: {=IFERROR(XLOOKUP(G20&H20,SAP!K:K,SAP!D:D,0,0),"")} -> 10315139 | J20: {=UPPER(XLOOKUP(G20&H20,SAP!K:K,SAP!E:E,0,0))} -> BOLSA HUNTINGTON 8"X4"X10" | K20: {=IFERROR(XLOOKUP(G20&H20,SAP!K:K,SAP!F:F,0,0),"")} -> 1800 | L20: {=IFERROR(XLOOKUP(G20&H20,SAP!K:K,SAP!G:G,0,0),"")} -> 6004.8 | M20: =IFERROR(L20/K20,0) -> 3.336 | N20: 0.2 | O20: =IFERROR(K20*(1+N20),0) -> 2160 | P20: 3341706 | Q20: 45922 | R20: {=IFERROR(XLOOKUP(G20&H20,SAP!K:K,SAP!H:H,0,0),"")} -> 45918 | S20: {=IFERROR(XLOOKUP(G20&H20,SAP!K:K,SAP!I:I,0,0),"")} -> 45945 | T20: 3000115091 | U20: 45993 | W20: ETA 10-Nov | X20: =IF(OR(U20<>0,V20<>0),"SCHEDULE","PENDING") -> SCHEDULE | Y20: =IF(U20<>0,IF(V20<>0,(V20-R20)/7,(U20-R20)/7),"") -> 10.714286 | Z20: =IF(Y20="","",IF(F20="BOLSAS",IF(Y20<=6,"IN TIME","DELAYED"),IF(F20="CAJAS",IF(Y20<=8,"IN TIME","DELAYED"),IF(Y20<=6,"IN TIME","DELAYED")))) -> DELAYED | AA20: =IF(AND(ISBLANK(U20),ISBLANK(V20)),"",IF(ISBLANK(V20),U20,V20)) -> 45993 | AB20: =CONCAT(G20,H20) -> 140204928620
A21: =IF(B21="BUFKOR INC.","BUFKOR",IF(B21="CHIPPENHOOK","CHIPPENHOOK","SPECIALTY")) -> SPECIALTY | B21: {=IFERROR(XLOOKUP(G21&H21,SAP!K:K,SAP!A:A,0,0),"")} -> BUFKOR INC- | C21: =IFERROR(IF(OR('MASTER PLAN'!$B$2:$B$81="CHIPPENHOOK",'MASTER PLAN'!$B$2:$B$81="BUFKOR INC."),"USA",IF('MASTER PLAN'!$B$2:$B$81="SIGMAQ MEXICO S.A DE C.V","MX","SP")),"") -> SP | D21: RODNEY LLOYD | E21: =IFERROR(VLOOKUP(D21,REFERENCIAS!A:B,2,0),"") -> KENEDY TOBAR | F21: BOLSAS | G21: 1402049318 | H21: 10 | I21: {=IFERROR(XLOOKUP(G21&H21,SAP!K:K,SAP!D:D,0,0),"")} -> 10330738 | J21: {=UPPER(XLOOKUP(G21&H21,SAP!K:K,SAP!E:E,0,0))} -> BOLSA WATERFALL JEWELERS 6-5"X3-5"X6-5" | K21: {=IFERROR(XLOOKUP(G21&H21,SAP!K:K,SAP!F:F,0,0),"")} -> 3000 | L21: {=IFERROR(XLOOKUP(G21&H21,SAP!K:K,SAP!G:G,0,0),"")} -> 7128 | M21: =IFERROR(L21/K21,0) -> 2.376 | N21: 0.2 | O21: =IFERROR(K21*(1+N21),0) -> 3600 | P21: 3341707 | Q21: 45922 | R21: {=IFERROR(XLOOKUP(G21&H21,SAP!K:K,SAP!H:H,0,0),"")} -> 45918 | S21: {=IFERROR(XLOOKUP(G21&H21,SAP!K:K,SAP!I:I,0,0),"")} -> 45968 | T21: 3000115938 | U21: 46010 | W21: Solped sin fecha en Basecamp. | X21: =IF(OR(U21<>0,V21<>0),"SCHEDULE","PENDING") -> SCHEDULE | Y21: =IF(U21<>0,IF(V21<>0,(V21-R21)/7,(U21-R21)/7),"") -> 13.142857 | Z21: =IF(Y21="","",IF(F21="BOLSAS",IF(Y21<=6,"IN TIME","DELAYED"),IF(F21="CAJAS",IF(Y21<=8,"IN TIME","DELAYED"),IF(Y21<=6,"IN TIME","DELAYED")))) -> DELAYED | AA21: =IF(AND(ISBLANK(U21),ISBLANK(V21)),"",IF(ISBLANK(V21),U21,V21)) -> 46010 | AB21: =CONCAT(G21,H21) -> 140204931810
A22: =IF(B22="BUFKOR INC.","BUFKOR",IF(B22="CHIPPENHOOK","CHIPPENHOOK","SPECIALTY")) -> SPECIALTY | B22: {=IFERROR(XLOOKUP(G22&H22,SAP!K:K,SAP!A:A,0,0),"")} -> BUFKOR INC- | C22: =IFERROR(IF(OR('MASTER PLAN'!$B$2:$B$81="CHIPPENHOOK",'MASTER PLAN'!$B$2:$B$81="BUFKOR INC."),"USA",IF('MASTER PLAN'!$B$2:$B$81="SIGMAQ MEXICO S.A DE C.V","MX","SP")),"") -> SP | D22: RODNEY LLOYD | E22: =IFERROR(VLOOKUP(D22,REFERENCIAS!A:B,2,0),"") -> KENEDY TOBAR | F22: BOLSAS | G22: 1402049318 | H22: 20 | I22: {=IFERROR(XLOOKUP(G22&H22,SAP!K:K,SAP!D:D,0,0),"")} -> 10330739 | J22: {=UPPER(XLOOKUP(G22&H22,SAP!K:K,SAP!E:E,0,0))} -> BOLSA WATERFALL JEWELERS 8"X4"X10" | K22: {=IFERROR(XLOOKUP(G22&H22,SAP!K:K,SAP!F:F,0,0),"")} -> 4000 | L22: {=IFERROR(XLOOKUP(G22&H22,SAP!K:K,SAP!G:G,0,0),"")} -> 12416 | M22: =IFERROR(L22/K22,0) -> 3.104 | N22: 0.2 | O22: =IFERROR(K22*(1+N22),0) -> 4800 | P22: 3341708 | Q22: 45922 | R22: {=IFERROR(XLOOKUP(G22&H22,SAP!K:K,SAP!H:H,0,0),"")} -> 45918 | S22: {=IFERROR(XLOOKUP(G22&H22,SAP!K:K,SAP!I:I,0,0),"")} -> 45968 | T22: 3000115938 | U22: 46010 | W22: Solped sin fecha en Basecamp. | X22: =IF(OR(U22<>0,V22<>0),"SCHEDULE","PENDING") -> SCHEDULE | Y22: =IF(U22<>0,IF(V22<>0,(V22-R22)/7,(U22-R22)/7),"") -> 13.142857 | Z22: =IF(Y22="","",IF(F22="BOLSAS",IF(Y22<=6,"IN TIME","DELAYED"),IF(F22="CAJAS",IF(Y22<=8,"IN TIME","DELAYED"),IF(Y22<=6,"IN TIME","DELAYED")))) -> DELAYED | AA22: =IF(AND(ISBLANK(U22),ISBLANK(V22)),"",IF(ISBLANK(V22),U22,V22)) -> 46010 | AB22: =CONCAT(G22,H22) -> 140204931820
A23: =IF(B23="BUFKOR INC.","BUFKOR",IF(B23="CHIPPENHOOK","CHIPPENHOOK","SPECIALTY")) -> SPECIALTY | B23: {=IFERROR(XLOOKUP(G23&H23,SAP!K:K,SAP!A:A,0,0),"")} -> BUFKOR INC- | C23: =IFERROR(IF(OR('MASTER PLAN'!$B$2:$B$81="CHIPPENHOOK",'MASTER PLAN'!$B$2:$B$81="BUFKOR INC."),"USA",IF('MASTER PLAN'!$B$2:$B$81="SIGMAQ MEXICO S.A DE C.V","MX","SP")),"") -> SP | D23: JENNIFER BEAGLE | E23: =IFERROR(VLOOKUP(D23,REFERENCIAS!A:B,2,0),"") -> JAVIER MOLINA | F23: BOLSAS | G23: 1402049332 | H23: 10 | I23: {=IFERROR(XLOOKUP(G23&H23,SAP!K:K,SAP!D:D,0,0),"")} -> 10315648 | J23: {=UPPER(XLOOKUP(G23&H23,SAP!K:K,SAP!E:E,0,0))} -> BOLSA SCOTT & CO 5"X4"X6" | K23: {=IFERROR(XLOOKUP(G23&H23,SAP!K:K,SAP!F:F,0,0),"")} -> 3000 | L23: {=IFERROR(XLOOKUP(G23&H23,SAP!K:K,SAP!G:G,0,0),"")} -> 2832 | M23: =IFERROR(L23/K23,0) -> 0.944 | N23: 0.2 | O23: =IFERROR(K23*(1+N23),0) -> 3600 | P23: 3341709 | Q23: 45922 | R23: {=IFERROR(XLOOKUP(G23&H23,SAP!K:K,SAP!H:H,0,0),"")} -> 45918 | S23: {=IFERROR(XLOOKUP(G23&H23,SAP!K:K,SAP!I:I,0,0),"")} -> 45966 | U23: 45979 | X23: =IF(OR(U23<>0,V23<>0),"SCHEDULE","PENDING") -> SCHEDULE | Y23: =IF(U23<>0,IF(V23<>0,(V23-R23)/7,(U23-R23)/7),"") -> 8.7142857 | Z23: =IF(Y23="","",IF(F23="BOLSAS",IF(Y23<=6,"IN TIME","DELAYED"),IF(F23="CAJAS",IF(Y23<=8,"IN TIME","DELAYED"),IF(Y23<=6,"IN TIME","DELAYED")))) -> DELAYED | AA23: =IF(AND(ISBLANK(U23),ISBLANK(V23)),"",IF(ISBLANK(V23),U23,V23)) -> 45979 | AB23: =CONCAT(G23,H23) -> 140204933210
A24: =IF(B24="BUFKOR INC.","BUFKOR",IF(B24="CHIPPENHOOK","CHIPPENHOOK","SPECIALTY")) -> SPECIALTY | B24: {=IFERROR(XLOOKUP(G24&H24,SAP!K:K,SAP!A:A,0,0),"")} -> BUFKOR INC- | C24: =IFERROR(IF(OR('MASTER PLAN'!$B$2:$B$81="CHIPPENHOOK",'MASTER PLAN'!$B$2:$B$81="BUFKOR INC."),"USA",IF('MASTER PLAN'!$B$2:$B$81="SIGMAQ MEXICO S.A DE C.V","MX","SP")),"") -> SP | D24: ROSA MARÍA TEJADA | E24: =IFERROR(VLOOKUP(D24,REFERENCIAS!A:B,2,0),"") -> ULISES HERNANDEZ | F24: BOLSAS | G24: 1402049342 | H24: 10 | I24: {=IFERROR(XLOOKUP(G24&H24,SAP!K:K,SAP!D:D,0,0),"")} -> 10317410 | J24: {=UPPER(XLOOKUP(G24&H24,SAP!K:K,SAP!E:E,0,0))} -> BOLSA SHARFMANS JLRS 6-5"X3-5"X6-5" | K24: {=IFERROR(XLOOKUP(G24&H24,SAP!K:K,SAP!F:F,0,0),"")} -> 1500 | L24: {=IFERROR(XLOOKUP(G24&H24,SAP!K:K,SAP!G:G,0,0),"")} -> 1380 | M24: =IFERROR(L24/K24,0) -> 0.92 | N24: 0.2 | O24: =IFERROR(K24*(1+N24),0) -> 1800 | P24: 3343125 | Q24: 45929 | R24: {=IFERROR(XLOOKUP(G24&H24,SAP!K:K,SAP!H:H,0,0),"")} -> 45918 | S24: {=IFERROR(XLOOKUP(G24&H24,SAP!K:K,SAP!I:I,0,0),"")} -> 45961 | U24: 45982 | X24: =IF(OR(U24<>0,V24<>0),"SCHEDULE","PENDING") -> SCHEDULE | Y24: =IF(U24<>0,IF(V24<>0,(V24-R24)/7,(U24-R24)/7),"") -> 9.1428571 | Z24: =IF(Y24="","",IF(F24="BOLSAS",IF(Y24<=6,"IN TIME","DELAYED"),IF(F24="CAJAS",IF(Y24<=8,"IN TIME","DELAYED"),IF(Y24<=6,"IN TIME","DELAYED")))) -> DELAYED | AA24: =IF(AND(ISBLANK(U24),ISBLANK(V24)),"",IF(ISBLANK(V24),U24,V24)) -> 45982 | AB24: =CONCAT(G24,H24) -> 140204934210
A25: =IF(B25="BUFKOR INC.","BUFKOR",IF(B25="CHIPPENHOOK","CHIPPENHOOK","SPECIALTY")) -> SPECIALTY | B25: {=IFERROR(XLOOKUP(G25&H25,SAP!K:K,SAP!A:A,0,0),"")} -> BUFKOR INC- | C25: =IFERROR(IF(OR('MASTER PLAN'!$B$2:$B$81="CHIPPENHOOK",'MASTER PLAN'!$B$2:$B$81="BUFKOR INC."),"USA",IF('MASTER PLAN'!$B$2:$B$81="SIGMAQ MEXICO S.A DE C.V","MX","SP")),"") -> SP | D25: ROSA MARÍA TEJADA | E25: =IFERROR(VLOOKUP(D25,REFERENCIAS!A:B,2,0),"") -> ULISES HERNANDEZ | F25: BOLSAS | G25: 1402049342 | H25: 20 | I25: {=IFERROR(XLOOKUP(G25&H25,SAP!K:K,SAP!D:D,0,0),"")} -> 10317411 | J25: {=UPPER(XLOOKUP(G25&H25,SAP!K:K,SAP!E:E,0,0))} -> BOLSA SHARFMANS JLRS 10"X4"X8" | K25: {=IFERROR(XLOOKUP(G25&H25,SAP!K:K,SAP!F:F,0,0),"")} -> 1500 | L25: {=IFERROR(XLOOKUP(G25&H25,SAP!K:K,SAP!G:G,0,0),"")} -> 1740 | M25: =IFERROR(L25/K25,0) -> 1.16 | N25: 0.2 | O25: =IFERROR(K25*(1+N25),0) -> 1800 | P25: 3343126 | Q25: 45929 | R25: {=IFERROR(XLOOKUP(G25&H25,SAP!K:K,SAP!H:H,0,0),"")} -> 45918 | S25: {=IFERROR(XLOOKUP(G25&H25,SAP!K:K,SAP!I:I,0,0),"")} -> 45961 | U25: 45986 | X25: =IF(OR(U25<>0,V25<>0),"SCHEDULE","PENDING") -> SCHEDULE | Y25: =IF(U25<>0,IF(V25<>0,(V25-R25)/7,(U25-R25)/7),"") -> 9.7142857 | Z25: =IF(Y25="","",IF(F25="BOLSAS",IF(Y25<=6,"IN TIME","DELAYED"),IF(F25="CAJAS",IF(Y25<=8,"IN TIME","DELAYED"),IF(Y25<=6,"IN TIME","DELAYED")))) -> DELAYED | AA25: =IF(AND(ISBLANK(U25),ISBLANK(V25)),"",IF(ISBLANK(V25),U25,V25)) -> 45986 | AB25: =CONCAT(G25,H25) -> 140204934220
A26: =IF(B26="BUFKOR INC.","BUFKOR",IF(B26="CHIPPENHOOK","CHIPPENHOOK","SPECIALTY")) -> CHIPPENHOOK | B26: {=IFERROR(XLOOKUP(G26&H26,SAP!K:K,SAP!A:A,0,0),"")} -> CHIPPENHOOK | C26: =IFERROR(IF(OR('MASTER PLAN'!$B$2:$B$81="CHIPPENHOOK",'MASTER PLAN'!$B$2:$B$81="BUFKOR INC."),"USA",IF('MASTER PLAN'!$B$2:$B$81="SIGMAQ MEXICO S.A DE C.V","MX","SP")),"") -> USA | D26: JUDY ISMAEL | E26: =IFERROR(VLOOKUP(D26,REFERENCIAS!A:B,2,0),"") -> SANTOS CORNEJO | F26: BOLSAS | G26: 1402049346 | H26: 10 | I26: {=IFERROR(XLOOKUP(G26&H26,SAP!K:K,SAP!D:D,0,0),"")} -> 10341615 | J26: {=UPPER(XLOOKUP(G26&H26,SAP!K:K,SAP!E:E,0,0))} -> BOLSA HELZBERG 10X2-5X8 IN FA | K26: {=IFERROR(XLOOKUP(G26&H26,SAP!K:K,SAP!F:F,0,0),"")} -> 20000 | L26: {=IFERROR(XLOOKUP(G26&H26,SAP!K:K,SAP!G:G,0,0),"")} -> 16000 | M26: =IFERROR(L26/K26,0) -> 0.8 | N26: 0.2 | O26: =IFERROR(K26*(1+N26),0) -> 24000 | P26: 3343127 | Q26: 45930 | R26: {=IFERROR(XLOOKUP(G26&H26,SAP!K:K,SAP!H:H,0,0),"")} -> 45918 | S26: {=IFERROR(XLOOKUP(G26&H26,SAP!K:K,SAP!I:I,0,0),"")} -> 45922 | U26: 45996 | W26: Únicamente restan 8,100 unidades por despachar. | X26: =IF(OR(U26<>0,V26<>0),"SCHEDULE","PENDING") -> SCHEDULE | Y26: =IF(U26<>0,IF(V26<>0,(V26-R26)/7,(U26-R26)/7),"") -> 11.142857 | Z26: =IF(Y26="","",IF(F26="BOLSAS",IF(Y26<=6,"IN TIME","DELAYED"),IF(F26="CAJAS",IF(Y26<=8,"IN TIME","DELAYED"),IF(Y26<=6,"IN TIME","DELAYED")))) -> DELAYED | AA26: =IF(AND(ISBLANK(U26),ISBLANK(V26)),"",IF(ISBLANK(V26),U26,V26)) -> 45996 | AB26: =CONCAT(G26,H26) -> 140204934610
A27: =IF(B27="BUFKOR INC.","BUFKOR",IF(B27="CHIPPENHOOK","CHIPPENHOOK","SPECIALTY")) -> SPECIALTY | B27: {=IFERROR(XLOOKUP(G27&H27,SAP!K:K,SAP!A:A,0,0),"")} -> BUFKOR INC- | C27: =IFERROR(IF(OR('MASTER PLAN'!$B$2:$B$81="CHIPPENHOOK",'MASTER PLAN'!$B$2:$B$81="BUFKOR INC."),"USA",IF('MASTER PLAN'!$B$2:$B$81="SIGMAQ MEXICO S.A DE C.V","MX","SP")),"") -> SP | D27: JENNIFER BEAGLE | E27: =IFERROR(VLOOKUP(D27,REFERENCIAS!A:B,2,0),"") -> JAVIER MOLINA | F27: BOLSAS | G27: 1402049349 | H27: 10 | I27: {=IFERROR(XLOOKUP(G27&H27,SAP!K:K,SAP!D:D,0,0),"")} -> 10341623 | J27: {=UPPER(XLOOKUP(G27&H27,SAP!K:K,SAP!E:E,0,0))} -> BOLSA WSHM WOS 10"X6"X10" FA | K27: {=IFERROR(XLOOKUP(G27&H27,SAP!K:K,SAP!F:F,0,0),"")} -> 15000 | L27: {=IFERROR(XLOOKUP(G27&H27,SAP!K:K,SAP!G:G,0,0),"")} -> 36720 | M27: =IFERROR(L27/K27,0) -> 2.448 | N27: 0.2 | O27: =IFERROR(K27*(1+N27),0) -> 18000 | P27: 3343130 | Q27: 45929 | R27: {=IFERROR(XLOOKUP(G27&H27,SAP!K:K,SAP!H:H,0,0),"")} -> 45923 | S27: {=IFERROR(XLOOKUP(G27&H27,SAP!K:K,SAP!I:I,0,0),"")} -> 45960 | U27: 46003 | W27: Atraso por problema de montaje en los pliegos de proveedor. | X27: =IF(OR(U27<>0,V27<>0),"SCHEDULE","PENDING") -> SCHEDULE | Y27: =IF(U27<>0,IF(V27<>0,(V27-R27)/7,(U27-R27)/7),"") -> 11.428571 | Z27: =IF(Y27="","",IF(F27="BOLSAS",IF(Y27<=6,"IN TIME","DELAYED"),IF(F27="CAJAS",IF(Y27<=8,"IN TIME","DELAYED"),IF(Y27<=6,"IN TIME","DELAYED")))) -> DELAYED | AA27: =IF(AND(ISBLANK(U27),ISBLANK(V27)),"",IF(ISBLANK(V27),U27,V27)) -> 46003 | AB27: =CONCAT(G27,H27) -> 140204934910
A28: =IF(B28="BUFKOR INC.","BUFKOR",IF(B28="CHIPPENHOOK","CHIPPENHOOK","SPECIALTY")) -> SPECIALTY | B28: {=IFERROR(XLOOKUP(G28&H28,SAP!K:K,SAP!A:A,0,0),"")} -> BUFKOR INC- | C28: =IFERROR(IF(OR('MASTER PLAN'!$B$2:$B$81="CHIPPENHOOK",'MASTER PLAN'!$B$2:$B$81="BUFKOR INC."),"USA",IF('MASTER PLAN'!$B$2:$B$81="SIGMAQ MEXICO S.A DE C.V","MX","SP")),"") -> SP | D28: JENNIFER BEAGLE | E28: =IFERROR(VLOOKUP(D28,REFERENCIAS!A:B,2,0),"") -> JAVIER MOLINA | F28: BOLSAS | G28: 1402049349 | H28: 20 | I28: {=IFERROR(XLOOKUP(G28&H28,SAP!K:K,SAP!D:D,0,0),"")} -> 10341624 | J28: {=UPPER(XLOOKUP(G28&H28,SAP!K:K,SAP!E:E,0,0))} -> BOLSA WSHN WOS 17"X7"X14" FA | K28: {=IFERROR(XLOOKUP(G28&H28,SAP!K:K,SAP!F:F,0,0),"")} -> 4000 | L28: {=IFERROR(XLOOKUP(G28&H28,SAP!K:K,SAP!G:G,0,0),"")} -> 18080 | M28: =IFERROR(L28/K28,0) -> 4.52 | N28: 0.2 | O28: =IFERROR(K28*(1+N28),0) -> 4800 | P28: 3343131 | Q28: 45929 | R28: {=IFERROR(XLOOKUP(G28&H28,SAP!K:K,SAP!H:H,0,0),"")} -> 45923 | S28: {=IFERROR(XLOOKUP(G28&H28,SAP!K:K,SAP!I:I,0,0),"")} -> 45960 | U28: 46003 | W28: Atraso por problema de montaje en los pliegos de proveedor. | X28: =IF(OR(U28<>0,V28<>0),"SCHEDULE","PENDING") -> SCHEDULE | Y28: =IF(U28<>0,IF(V28<>0,(V28-R28)/7,(U28-R28)/7),"") -> 11.428571 | Z28: =IF(Y28="","",IF(F28="BOLSAS",IF(Y28<=6,"IN TIME","DELAYED"),IF(F28="CAJAS",IF(Y28<=8,"IN TIME","DELAYED"),IF(Y28<=6,"IN TIME","DELAYED")))) -> DELAYED | AA28: =IF(AND(ISBLANK(U28),ISBLANK(V28)),"",IF(ISBLANK(V28),U28,V28)) -> 46003 | AB28: =CONCAT(G28,H28) -> 140204934920
A29: =IF(B29="BUFKOR INC.","BUFKOR",IF(B29="CHIPPENHOOK","CHIPPENHOOK","SPECIALTY")) -> SPECIALTY | B29: {=IFERROR(XLOOKUP(G29&H29,SAP!K:K,SAP!A:A,0,0),"")} -> BUFKOR INC- | C29: =IFERROR(IF(OR('MASTER PLAN'!$B$2:$B$81="CHIPPENHOOK",'MASTER PLAN'!$B$2:$B$81="BUFKOR INC."),"USA",IF('MASTER PLAN'!$B$2:$B$81="SIGMAQ MEXICO S.A DE C.V","MX","SP")),"") -> SP | D29: JENNIFER BEAGLE | E29: =IFERROR(VLOOKUP(D29,REFERENCIAS!A:B,2,0),"") -> JAVIER MOLINA | F29: BOLSAS | G29: 1402049350 | H29: 10 | I29: {=IFERROR(XLOOKUP(G29&H29,SAP!K:K,SAP!D:D,0,0),"")} -> 10341618 | J29: {=UPPER(XLOOKUP(G29&H29,SAP!K:K,SAP!E:E,0,0))} -> BOLSA WSMJ MAYORS WOS 6-5"X3-5"X6-5" FA | K29: {=IFERROR(XLOOKUP(G29&H29,SAP!K:K,SAP!F:F,0,0),"")} -> 4000 | L29: {=IFERROR(XLOOKUP(G29&H29,SAP!K:K,SAP!G:G,0,0),"")} -> 6688 | M29: =IFERROR(L29/K29,0) -> 1.672 | N29: 0.2 | O29: =IFERROR(K29*(1+N29),0) -> 4800 | P29: 3343132 | Q29: 45929 | R29: {=IFERROR(XLOOKUP(G29&H29,SAP!K:K,SAP!H:H,0,0),"")} -> 45923 | S29: {=IFERROR(XLOOKUP(G29&H29,SAP!K:K,SAP!I:I,0,0),"")} -> 45959 | U29: 46003 | W29: Atraso por problema de montaje en los pliegos de proveedor. | X29: =IF(OR(U29<>0,V29<>0),"SCHEDULE","PENDING") -> SCHEDULE | Y29: =IF(U29<>0,IF(V29<>0,(V29-R29)/7,(U29-R29)/7),"") -> 11.428571 | Z29: =IF(Y29="","",IF(F29="BOLSAS",IF(Y29<=6,"IN TIME","DELAYED"),IF(F29="CAJAS",IF(Y29<=8,"IN TIME","DELAYED"),IF(Y29<=6,"IN TIME","DELAYED")))) -> DELAYED | AA29: =IF(AND(ISBLANK(U29),ISBLANK(V29)),"",IF(ISBLANK(V29),U29,V29)) -> 46003 | AB29: =CONCAT(G29,H29) -> 140204935010
A30: =IF(B30="BUFKOR INC.","BUFKOR",IF(B30="CHIPPENHOOK","CHIPPENHOOK","SPECIALTY")) -> SPECIALTY | B30: {=IFERROR(XLOOKUP(G30&H30,SAP!K:K,SAP!A:A,0,0),"")} -> BUFKOR INC- | C30: =IFERROR(IF(OR('MASTER PLAN'!$B$2:$B$81="CHIPPENHOOK",'MASTER PLAN'!$B$2:$B$81="BUFKOR INC."),"USA",IF('MASTER PLAN'!$B$2:$B$81="SIGMAQ MEXICO S.A DE C.V","MX","SP")),"") -> SP | D30: JENNIFER BEAGLE | E30: =IFERROR(VLOOKUP(D30,REFERENCIAS!A:B,2,0),"") -> JAVIER MOLINA | F30: BOLSAS | G30: 1402049350 | H30: 20 | I30: {=IFERROR(XLOOKUP(G30&H30,SAP!K:K,SAP!D:D,0,0),"")} -> 10341620 | J30: {=UPPER(XLOOKUP(G30&H30,SAP!K:K,SAP!E:E,0,0))} -> BOLSA WSMJ MAYORS WOS 10"X6"X10" FA | K30: {=IFERROR(XLOOKUP(G30&H30,SAP!K:K,SAP!F:F,0,0),"")} -> 12000 | L30: {=IFERROR(XLOOKUP(G30&H30,SAP!K:K,SAP!G:G,0,0),"")} -> 29760 | M30: =IFERROR(L30/K30,0) -> 2.48 | N30: 0.2 | O30: =IFERROR(K30*(1+N30),0) -> 14400 | P30: 3343133 | Q30: 45929 | R30: {=IFERROR(XLOOKUP(G30&H30,SAP!K:K,SAP!H:H,0,0),"")} -> 45923 | S30: {=IFERROR(XLOOKUP(G30&H30,SAP!K:K,SAP!I:I,0,0),"")} -> 45959 | U30: 46003 | W30: Atraso por problema de montaje en los pliegos de proveedor. | X30: =IF(OR(U30<>0,V30<>0),"SCHEDULE","PENDING") -> SCHEDULE | Y30: =IF(U30<>0,IF(V30<>0,(V30-R30)/7,(U30-R30)/7),"") -> 11.428571 | Z30: =IF(Y30="","",IF(F30="BOLSAS",IF(Y30<=6,"IN TIME","DELAYED"),IF(F30="CAJAS",IF(Y30<=8,"IN TIME","DELAYED"),IF(Y30<=6,"IN TIME","DELAYED")))) -> DELAYED | AA30: =IF(AND(ISBLANK(U30),ISBLANK(V30)),"",IF(ISBLANK(V30),U30,V30)) -> 46003 | AB30: =CONCAT(G30,H30) -> 140204935020
A31: =IF(B31="BUFKOR INC.","BUFKOR",IF(B31="CHIPPENHOOK","CHIPPENHOOK","SPECIALTY")) -> SPECIALTY | B31: {=IFERROR(XLOOKUP(G31&H31,SAP!K:K,SAP!A:A,0,0),"")} -> BUFKOR INC- | C31: =IFERROR(IF(OR('MASTER PLAN'!$B$2:$B$81="CHIPPENHOOK",'MASTER PLAN'!$B$2:$B$81="BUFKOR INC."),"USA",IF('MASTER PLAN'!$B$2:$B$81="SIGMAQ MEXICO S.A DE C.V","MX","SP")),"") -> SP | D31: JENNIFER BEAGLE | E31: =IFERROR(VLOOKUP(D31,REFERENCIAS!A:B,2,0),"") -> JAVIER MOLINA | F31: BOLSAS | G31: 1402049350 | H31: 30 | I31: {=IFERROR(XLOOKUP(G31&H31,SAP!K:K,SAP!D:D,0,0),"")} -> 10341619 | J31: {=UPPER(XLOOKUP(G31&H31,SAP!K:K,SAP!E:E,0,0))} -> BOLSA WSMJ MAYORS WOS 17"X7"X14" FA | K31: {=IFERROR(XLOOKUP(G31&H31,SAP!K:K,SAP!F:F,0,0),"")} -> 4000 | L31: {=IFERROR(XLOOKUP(G31&H31,SAP!K:K,SAP!G:G,0,0),"")} -> 18336 | M31: =IFERROR(L31/K31,0) -> 4.584 | N31: 0.2 | O31: =IFERROR(K31*(1+N31),0) -> 4800 | P31: 3343134 | Q31: 45929 | R31: {=IFERROR(XLOOKUP(G31&H31,SAP!K:K,SAP!H:H,0,0),"")} -> 45923 | S31: {=IFERROR(XLOOKUP(G31&H31,SAP!K:K,SAP!I:I,0,0),"")} -> 45959 | U31: 46003 | W31: Atraso por problema de montaje en los pliegos de proveedor. | X31: =IF(OR(U31<>0,V31<>0),"SCHEDULE","PENDING") -> SCHEDULE | Y31: =IF(U31<>0,IF(V31<>0,(V31-R31)/7,(U31-R31)/7),"") -> 11.428571 | Z31: =IF(Y31="","",IF(F31="BOLSAS",IF(Y31<=6,"IN TIME","DELAYED"),IF(F31="CAJAS",IF(Y31<=8,"IN TIME","DELAYED"),IF(Y31<=6,"IN TIME","DELAYED")))) -> DELAYED | AA31: =IF(AND(ISBLANK(U31),ISBLANK(V31)),"",IF(ISBLANK(V31),U31,V31)) -> 46003 | AB31: =CONCAT(G31,H31) -> 140204935030
A32: =IF(B32="BUFKOR INC.","BUFKOR",IF(B32="CHIPPENHOOK","CHIPPENHOOK","SPECIALTY")) -> SPECIALTY | B32: {=IFERROR(XLOOKUP(G32&H32,SAP!K:K,SAP!A:A,0,0),"")} -> BUFKOR INC- | C32: =IFERROR(IF(OR('MASTER PLAN'!$B$2:$B$81="CHIPPENHOOK",'MASTER PLAN'!$B$2:$B$81="BUFKOR INC."),"USA",IF('MASTER PLAN'!$B$2:$B$81="SIGMAQ MEXICO S.A DE C.V","MX","SP")),"") -> SP | D32: RODNEY LLOYD | E32: =IFERROR(VLOOKUP(D32,REFERENCIAS!A:B,2,0),"") -> KENEDY TOBAR | F32: BOLSAS | G32: 1402049351 | H32: 10 | I32: {=IFERROR(XLOOKUP(G32&H32,SAP!K:K,SAP!D:D,0,0),"")} -> 10330738 | J32: {=UPPER(XLOOKUP(G32&H32,SAP!K:K,SAP!E:E,0,0))} -> BOLSA WATERFALL JEWELERS 6-5"X3-5"X6-5" | K32: {=IFERROR(XLOOKUP(G32&H32,SAP!K:K,SAP!F:F,0,0),"")} -> 2000 | L32: {=IFERROR(XLOOKUP(G32&H32,SAP!K:K,SAP!G:G,0,0),"")} -> 4752 | M32: =IFERROR(L32/K32,0) -> 2.376 | N32: 0.2 | O32: =IFERROR(K32*(1+N32),0) -> 2400 | P32: 3343201 | Q32: 45929 | R32: {=IFERROR(XLOOKUP(G32&H32,SAP!K:K,SAP!H:H,0,0),"")} -> 45923 | S32: {=IFERROR(XLOOKUP(G32&H32,SAP!K:K,SAP!I:I,0,0),"")} -> 45968 | U32: 46010 | X32: =IF(OR(U32<>0,V32<>0),"SCHEDULE","PENDING") -> SCHEDULE | Y32: =IF(U32<>0,IF(V32<>0,(V32-R32)/7,(U32-R32)/7),"") -> 12.428571 | Z32: =IF(Y32="","",IF(F32="BOLSAS",IF(Y32<=6,"IN TIME","DELAYED"),IF(F32="CAJAS",IF(Y32<=8,"IN TIME","DELAYED"),IF(Y32<=6,"IN TIME","DELAYED")))) -> DELAYED | AA32: =IF(AND(ISBLANK(U32),ISBLANK(V32)),"",IF(ISBLANK(V32),U32,V32)) -> 46010 | AB32: =CONCAT(G32,H32) -> 140204935110
A33: =IF(B33="BUFKOR INC.","BUFKOR",IF(B33="CHIPPENHOOK","CHIPPENHOOK","SPECIALTY")) -> SPECIALTY | B33: {=IFERROR(XLOOKUP(G33&H33,SAP!K:K,SAP!A:A,0,0),"")} -> BUFKOR INC- | C33: =IFERROR(IF(OR('MASTER PLAN'!$B$2:$B$81="CHIPPENHOOK",'MASTER PLAN'!$B$2:$B$81="BUFKOR INC."),"USA",IF('MASTER PLAN'!$B$2:$B$81="SIGMAQ MEXICO S.A DE C.V","MX","SP")),"") -> SP | D33: RODNEY LLOYD | E33: =IFERROR(VLOOKUP(D33,REFERENCIAS!A:B,2,0),"") -> KENEDY TOBAR | F33: BOLSAS | G33: 1402049351 | H33: 20 | I33: {=IFERROR(XLOOKUP(G33&H33,SAP!K:K,SAP!D:D,0,0),"")} -> 10330739 | J33: {=UPPER(XLOOKUP(G33&H33,SAP!K:K,SAP!E:E,0,0))} -> BOLSA WATERFALL JEWELERS 8"X4"X10" | K33: {=IFERROR(XLOOKUP(G33&H33,SAP!K:K,SAP!F:F,0,0),"")} -> 1000 | L33: {=IFERROR(XLOOKUP(G33&H33,SAP!K:K,SAP!G:G,0,0),"")} -> 3104 | M33: =IFERROR(L33/K33,0) -> 3.104 | N33: 0.2 | O33: =IFERROR(K33*(1+N33),0) -> 1200 | P33: 3343202 | Q33: 45929 | R33: {=IFERROR(XLOOKUP(G33&H33,SAP!K:K,SAP!H:H,0,0),"")} -> 45923 | S33: {=IFERROR(XLOOKUP(G33&H33,SAP!K:K,SAP!I:I,0,0),"")} -> 45968 | U33: 46010 | X33: =IF(OR(U33<>0,V33<>0),"SCHEDULE","PENDING") -> SCHEDULE | Y33: =IF(U33<>0,IF(V33<>0,(V33-R33)/7,(U33-R33)/7),"") -> 12.428571 | Z33: =IF(Y33="","",IF(F33="BOLSAS",IF(Y33<=6,"IN TIME","DELAYED"),IF(F33="CAJAS",IF(Y33<=8,"IN TIME","DELAYED"),IF(Y33<=6,"IN TIME","DELAYED")))) -> DELAYED | AA33: =IF(AND(ISBLANK(U33),ISBLANK(V33)),"",IF(ISBLANK(V33),U33,V33)) -> 46010 | AB33: =CONCAT(G33,H33) -> 140204935120
A34: =IF(B34="BUFKOR INC.","BUFKOR",IF(B34="CHIPPENHOOK","CHIPPENHOOK","SPECIALTY")) -> SPECIALTY | B34: {=IFERROR(XLOOKUP(G34&H34,SAP!K:K,SAP!A:A,0,0),"")} -> BUFKOR INC- | C34: =IFERROR(IF(OR('MASTER PLAN'!$B$2:$B$81="CHIPPENHOOK",'MASTER PLAN'!$B$2:$B$81="BUFKOR INC."),"USA",IF('MASTER PLAN'!$B$2:$B$81="SIGMAQ MEXICO S.A DE C.V","MX","SP")),"") -> SP | D34: ROSA MARÍA TEJADA | E34: =IFERROR(VLOOKUP(D34,REFERENCIAS!A:B,2,0),"") -> ULISES HERNANDEZ | F34: BOLSAS | G34: 1402049355 | H34: 10 | I34: {=IFERROR(XLOOKUP(G34&H34,SAP!K:K,SAP!D:D,0,0),"")} -> 10264307 | J34: {=UPPER(XLOOKUP(G34&H34,SAP!K:K,SAP!E:E,0,0))} -> BOLSA WALKER CHRISTOPHER 6-5X3X9 | K34: {=IFERROR(XLOOKUP(G34&H34,SAP!K:K,SAP!F:F,0,0),"")} -> 1500 | L34: {=IFERROR(XLOOKUP(G34&H34,SAP!K:K,SAP!G:G,0,0),"")} -> 2190 | M34: =IFERROR(L34/K34,0) -> 1.46 | N34: 0.2 | O34: =IFERROR(K34*(1+N34),0) -> 1800 | P34: 3343214 | Q34: 45929 | R34: {=IFERROR(XLOOKUP(G34&H34,SAP!K:K,SAP!H:H,0,0),"")} -> 45923 | S34: {=IFERROR(XLOOKUP(G34&H34,SAP!K:K,SAP!I:I,0,0),"")} -> 45989 | T34: 3000115937 | U34: 46010 | W34: ETA 18-Nov | X34: =IF(OR(U34<>0,V34<>0),"SCHEDULE","PENDING") -> SCHEDULE | Y34: =IF(U34<>0,IF(V34<>0,(V34-R34)/7,(U34-R34)/7),"") -> 12.428571 | Z34: =IF(Y34="","",IF(F34="BOLSAS",IF(Y34<=6,"IN TIME","DELAYED"),IF(F34="CAJAS",IF(Y34<=8,"IN TIME","DELAYED"),IF(Y34<=6,"IN TIME","DELAYED")))) -> DELAYED | AA34: =IF(AND(ISBLANK(U34),ISBLANK(V34)),"",IF(ISBLANK(V34),U34,V34)) -> 46010 | AB34: =CONCAT(G34,H34) -> 140204935510
A35: =IF(B35="BUFKOR INC.","BUFKOR",IF(B35="CHIPPENHOOK","CHIPPENHOOK","SPECIALTY")) -> SPECIALTY | B35: {=IFERROR(XLOOKUP(G35&H35,SAP!K:K,SAP!A:A,0,0),"")} -> BUFKOR INC- | C35: =IFERROR(IF(OR('MASTER PLAN'!$B$2:$B$81="CHIPPENHOOK",'MASTER PLAN'!$B$2:$B$81="BUFKOR INC."),"USA",IF('MASTER PLAN'!$B$2:$B$81="SIGMAQ MEXICO S.A DE C.V","MX","SP")),"") -> SP | D35: ENOC MADRIL | E35: =IFERROR(VLOOKUP(D35,REFERENCIAS!A:B,2,0),"") -> REYNALDO CARRANZA | F35: BOLSAS | G35: 1402049357 | H35: 10 | I35: {=IFERROR(XLOOKUP(G35&H35,SAP!K:K,SAP!D:D,0,0),"")} -> 10341444 | J35: {=UPPER(XLOOKUP(G35&H35,SAP!K:K,SAP!E:E,0,0))} -> BOLSA GREBITUS 11X4X8 IN FL | K35: {=IFERROR(XLOOKUP(G35&H35,SAP!K:K,SAP!F:F,0,0),"")} -> 2000 | L35: {=IFERROR(XLOOKUP(G35&H35,SAP!K:K,SAP!G:G,0,0),"")} -> 2304 | M35: =IFERROR(L35/K35,0) -> 1.152 | N35: 0.2 | O35: =IFERROR(K35*(1+N35),0) -> 2400 | P35: 3343203 | Q35: 45929 | R35: {=IFERROR(XLOOKUP(G35&H35,SAP!K:K,SAP!H:H,0,0),"")} -> 45923 | S35: {=IFERROR(XLOOKUP(G35&H35,SAP!K:K,SAP!I:I,0,0),"")} -> 45961 | U35: 45980 | X35: =IF(OR(U35<>0,V35<>0),"SCHEDULE","PENDING") -> SCHEDULE | Y35: =IF(U35<>0,IF(V35<>0,(V35-R35)/7,(U35-R35)/7),"") -> 8.1428571 | Z35: =IF(Y35="","",IF(F35="BOLSAS",IF(Y35<=6,"IN TIME","DELAYED"),IF(F35="CAJAS",IF(Y35<=8,"IN TIME","DELAYED"),IF(Y35<=6,"IN TIME","DELAYED")))) -> DELAYED | AA35: =IF(AND(ISBLANK(U35),ISBLANK(V35)),"",IF(ISBLANK(V35),U35,V35)) -> 45980 | AB35: =CONCAT(G35,H35) -> 140204935710
A36: =IF(B36="BUFKOR INC.","BUFKOR",IF(B36="CHIPPENHOOK","CHIPPENHOOK","SPECIALTY")) -> SPECIALTY | B36: {=IFERROR(XLOOKUP(G36&H36,SAP!K:K,SAP!A:A,0,0),"")} -> BUFKOR INC- | C36: =IFERROR(IF(OR('MASTER PLAN'!$B$2:$B$81="CHIPPENHOOK",'MASTER PLAN'!$B$2:$B$81="BUFKOR INC."),"USA",IF('MASTER PLAN'!$B$2:$B$81="SIGMAQ MEXICO S.A DE C.V","MX","SP")),"") -> SP | D36: JENNIFER BEAGLE | E36: =IFERROR(VLOOKUP(D36,REFERENCIAS!A:B,2,0),"") -> JAVIER MOLINA | F36: BOLSAS | G36: 1402049358 | H36: 10 | I36: {=IFERROR(XLOOKUP(G36&H36,SAP!K:K,SAP!D:D,0,0),"")} -> 10315151 | J36: {=UPPER(XLOOKUP(G36&H36,SAP!K:K,SAP!E:E,0,0))} -> BOLSA JON'S FINE JEWELRY 5"X4"X7" | K36: {=IFERROR(XLOOKUP(G36&H36,SAP!K:K,SAP!F:F,0,0),"")} -> 2000 | L36: {=IFERROR(XLOOKUP(G36&H36,SAP!K:K,SAP!G:G,0,0),"")} -> 3344 | M36: =IFERROR(L36/K36,0) -> 1.672 | N36: 0.2 | O36: =IFERROR(K36*(1+N36),0) -> 2400 | P36: 3343204 | Q36: 45929 | R36: {=IFERROR(XLOOKUP(G36&H36,SAP!K:K,SAP!H:H,0,0),"")} -> 45922 | S36: {=IFERROR(XLOOKUP(G36&H36,SAP!K:K,SAP!I:I,0,0),"")} -> 45687 | T36: 3000115950 | U36: 46031 | W36: ETA 25-Nov | X36: =IF(OR(U36<>0,V36<>0),"SCHEDULE","PENDING") -> SCHEDULE | Y36: =IF(U36<>0,IF(V36<>0,(V36-R36)/7,(U36-R36)/7),"") -> 15.571429 | Z36: =IF(Y36="","",IF(F36="BOLSAS",IF(Y36<=6,"IN TIME","DELAYED"),IF(F36="CAJAS",IF(Y36<=8,"IN TIME","DELAYED"),IF(Y36<=6,"IN TIME","DELAYED")))) -> DELAYED | AA36: =IF(AND(ISBLANK(U36),ISBLANK(V36)),"",IF(ISBLANK(V36),U36,V36)) -> 46031 | AB36: =CONCAT(G36,H36) -> 140204935810
